Workbook

Sheet GRILLA
A1: N° de Ruta | B1: Nombre y apellido | C1: Concurso de Marcas | O1: Vigencia: 3.08 al 29.08 | Q1: MARCAS >= 50% | AA1: MARCAS >=100%
C2: Hileret | D2: Elvive | E2: Carefree Siempre libre | F2: Calipso Nosotras | G2: Elegante | H2: Cif | I2: Arlistan Cruz Malta | J2: Categoria Pescados | K2: Downy | L2: PROMEDIO | M2: Ranking | O2: PREMIOS: | Q2: Hileret | R2: Elvive | S2: Carefree Siempre libre | T2: Calipso Nosotras | U2: Elegante | V2: Cif | W2: Arlistan Cruz Malta | X2: Categoria Pescados | Y2: Downy | Z2: TOTAL | AA2: Hileret | AB2: Elvive | AC2: Carefree Siempre libre | AD2: Calipso Nosotras | AE2: Elegante | AF2: Cif | AG2: Arlistan Cruz Malta | AH2: Categoria Pescados | AI2: Downy | AJ2: TOTAL
A3: 455 | B3: CISNEROS JONATHAN | C3: =VLOOKUP(A3,INCENTIVO!A:E,5,0) -> 0.076923077 | D3: =VLOOKUP(A3,INCENTIVO!A:H,8,0) -> 0.53846154 | E3: =VLOOKUP(A3,INCENTIVO!A:K,11,0) -> 0 | F3: =VLOOKUP(A3,INCENTIVO!A:N,14,0) -> 0.071428571 | G3: =VLOOKUP(A3,INCENTIVO!A:Q,17,0) -> 0 | H3: =VLOOKUP(A3,INCENTIVO!A:T,20,0) -> 0.15 | I3: =VLOOKUP(A3,INCENTIVO!A:W,23,0) -> 0.066666667 | J3: =VLOOKUP(A3,INCENTIVO!A:Z,26,0) -> 0.037470708 | K3: =VLOOKUP(A3,INCENTIVO!A:AC,29,0) -> 0.45454545 | L3: =AVERAGE(C3:J3) -> 0.11761882 | M3: =VLOOKUP(A3,RANKING!A:C,3,0) -> 78 | O3: Escala 1 = 5 marcas $125.000 | Q3: =IF(C3>=50%,1,0) -> 0 | R3: =IF(D3>=50%,1,0) -> 1 | S3: =IF(E3>=50%,1,0) -> 0 | T3: =IF(F3>=50%,1,0) -> 0 | U3: =IF(G3>=50%,1,0) -> 0 | V3: =IF(H3>=50%,1,0) -> 0 | W3: =IF(I3>=50%,1,0) -> 0 | X3: =IF(J3>=50%,1,0) -> 0 | Y3: =IF(K3>=50%,1,0) -> 0 | Z3: =SUM(Q3:Y3) -> 1 | AA3: =IF(C3>=100%,1,0) -> 0 | AB3: =IF(D3>=100%,1,0) -> 0 | AC3: =IF(E3>=100%,1,0) -> 0 | AD3: =IF(F3>=100%,1,0) -> 0 | AE3: =IF(G3>=100%,1,0) -> 0 | AF3: =IF(H3>=100%,1,0) -> 0 | AG3: =IF(I3>=100%,1,0) -> 0 | AH3: =IF(J3>=100%,1,0) -> 0 | AI3: =IF(K3>=100%,1,0) -> 0 | AJ3: =SUM(AA3:AI3) -> 0
A4: 480 | B4: MEDINA NICOLAS | C4: =VLOOKUP(A4,INCENTIVO!A:E,5,0) -> 0.2 | D4: =VLOOKUP(A4,INCENTIVO!A:H,8,0) -> 0.5 | E4: =VLOOKUP(A4,INCENTIVO!A:K,11,0) -> 0.29411765 | F4: =VLOOKUP(A4,INCENTIVO!A:N,14,0) -> 0.17647059 | G4: =VLOOKUP(A4,INCENTIVO!A:Q,17,0) -> 0.15384615 | H4: =VLOOKUP(A4,INCENTIVO!A:T,20,0) -> 0.2173913 | I4: =VLOOKUP(A4,INCENTIVO!A:W,23,0) -> 0 | J4: =VLOOKUP(A4,INCENTIVO!A:Z,26,0) -> 0.32497674 | K4: =VLOOKUP(A4,INCENTIVO!A:AC,29,0) -> 0.15384615 | L4: =AVERAGE(C4:J4) -> 0.2333503 | M4: =VLOOKUP(A4,RANKING!A:C,3,0) -> 34 | O4: Escala 2 = 7 marcas $250.000 | Q4: =IF(C4>=50%,1,0) -> 0 | R4: =IF(D4>=50%,1,0) -> 1 | S4: =IF(E4>=50%,1,0) -> 0 | T4: =IF(F4>=50%,1,0) -> 0 | U4: =IF(G4>=50%,1,0) -> 0 | V4: =IF(H4>=50%,1,0) -> 0 | W4: =IF(I4>=50%,1,0) -> 0 | X4: =IF(J4>=50%,1,0) -> 0 | Y4: =IF(K4>=50%,1,0) -> 0 | Z4: =SUM(Q4:Y4) -> 1 | AA4: =IF(C4>=100%,1,0) -> 0 | AB4: =IF(D4>=100%,1,0) -> 0 | AC4: =IF(E4>=100%,1,0) -> 0 | AD4: =IF(F4>=100%,1,0) -> 0 | AE4: =IF(G4>=100%,1,0) -> 0 | AF4: =IF(H4>=100%,1,0) -> 0 | AG4: =IF(I4>=100%,1,0) -> 0 | AH4: =IF(J4>=100%,1,0) -> 0 | AI4: =IF(K4>=100%,1,0) -> 0 | AJ4: =SUM(AA4:AI4) -> 0
A5: 430 | B5: DELAMANO BRIAN | C5: =VLOOKUP(A5,INCENTIVO!A:E,5,0) -> 0.16666667 | D5: =VLOOKUP(A5,INCENTIVO!A:H,8,0) -> 1.4615385 | E5: =VLOOKUP(A5,INCENTIVO!A:K,11,0) -> 0.53846154 | F5: =VLOOKUP(A5,INCENTIVO!A:N,14,0) -> 0 | G5: =VLOOKUP(A5,INCENTIVO!A:Q,17,0) -> 0.1 | H5: =VLOOKUP(A5,INCENTIVO!A:T,20,0) -> 0.26315789 | I5: =VLOOKUP(A5,INCENTIVO!A:W,23,0) -> 0.21428571 | J5: =VLOOKUP(A5,INCENTIVO!A:Z,26,0) -> 0.071921491 | K5: =VLOOKUP(A5,INCENTIVO!A:AC,29,0) -> 0.6 | L5: =AVERAGE(C5:J5) -> 0.35200397 | M5: =VLOOKUP(A5,RANKING!A:C,3,0) -> 12 | O5: Escala 3 = 9 marcas $300.000 | Q5: =IF(C5>=50%,1,0) -> 0 | R5: =IF(D5>=50%,1,0) -> 1 | S5: =IF(E5>=50%,1,0) -> 1 | T5: =IF(F5>=50%,1,0) -> 0 | U5: =IF(G5>=50%,1,0) -> 0 | V5: =IF(H5>=50%,1,0) -> 0 | W5: =IF(I5>=50%,1,0) -> 0 | X5: =IF(J5>=50%,1,0) -> 0 | Y5: =IF(K5>=50%,1,0) -> 1 | Z5: =SUM(Q5:Y5) -> 3 | AA5: =IF(C5>=100%,1,0) -> 0 | AB5: =IF(D5>=100%,1,0) -> 1 | AC5: =IF(E5>=100%,1,0) -> 0 | AD5: =IF(F5>=100%,1,0) -> 0 | AE5: =IF(G5>=100%,1,0) -> 0 | AF5: =IF(H5>=100%,1,0) -> 0 | AG5: =IF(I5>=100%,1,0) -> 0 | AH5: =IF(J5>=100%,1,0) -> 0 | AI5: =IF(K5>=100%,1,0) -> 0 | AJ5: =SUM(AA5:AI5) -> 1
A6: 415 | B6: OLGUIN PATRICIA | C6: =VLOOKUP(A6,INCENTIVO!A:E,5,0) -> 0.53333333 | D6: =VLOOKUP(A6,INCENTIVO!A:H,8,0) -> 0.25 | E6: =VLOOKUP(A6,INCENTIVO!A:K,11,0) -> 0.29411765 | F6: =VLOOKUP(A6,INCENTIVO!A:N,14,0) -> 0.058823529 | G6: =VLOOKUP(A6,INCENTIVO!A:Q,17,0) -> 0 | H6: =VLOOKUP(A6,INCENTIVO!A:T,20,0) -> 0.12 | I6: =VLOOKUP(A6,INCENTIVO!A:W,23,0) -> 0.27777778 | J6: =VLOOKUP(A6,INCENTIVO!A:Z,26,0) -> 0.13108461 | K6: =VLOOKUP(A6,INCENTIVO!A:AC,29,0) -> 0.15384615 | L6: =AVERAGE(C6:J6) -> 0.20814211 | M6: =VLOOKUP(A6,RANKING!A:C,3,0) -> 38 | O6: TODAS LAS MARCAS DEBEN ESTAR AL 50% | Q6: =IF(C6>=50%,1,0) -> 1 | R6: =IF(D6>=50%,1,0) -> 0 | S6: =IF(E6>=50%,1,0) -> 0 | T6: =IF(F6>=50%,1,0) -> 0 | U6: =IF(G6>=50%,1,0) -> 0 | V6: =IF(H6>=50%,1,0) -> 0 | W6: =IF(I6>=50%,1,0) -> 0 | X6: =IF(J6>=50%,1,0) -> 0 | Y6: =IF(K6>=50%,1,0) -> 0 | Z6: =SUM(Q6:Y6) -> 1 | AA6: =IF(C6>=100%,1,0) -> 0 | AB6: =IF(D6>=100%,1,0) -> 0 | AC6: =IF(E6>=100%,1,0) -> 0 | AD6: =IF(F6>=100%,1,0) -> 0 | AE6: =IF(G6>=100%,1,0) -> 0 | AF6: =IF(H6>=100%,1,0) -> 0 | AG6: =IF(I6>=100%,1,0) -> 0 | AH6: =IF(J6>=100%,1,0) -> 0 | AI6: =IF(K6>=100%,1,0) -> 0 | AJ6: =SUM(AA6:AI6) -> 0
A7: 431 | B7: FERNANDEZ MELANY | C7: =VLOOKUP(A7,INCENTIVO!A:E,5,0) -> 0.76923077 | D7: =VLOOKUP(A7,INCENTIVO!A:H,8,0) -> 0.64285714 | E7: =VLOOKUP(A7,INCENTIVO!A:K,11,0) -> 0.6 | F7: =VLOOKUP(A7,INCENTIVO!A:N,14,0) -> 0.26666667 | G7: =VLOOKUP(A7,INCENTIVO!A:Q,17,0) -> 0.33333333 | H7: =VLOOKUP(A7,INCENTIVO!A:T,20,0) -> 0.28571429 | I7: =VLOOKUP(A7,INCENTIVO!A:W,23,0) -> 0.3125 | J7: =VLOOKUP(A7,INCENTIVO!A:Z,26,0) -> 0.39171989 | K7: =VLOOKUP(A7,INCENTIVO!A:AC,29,0) -> 0.25 | L7: =AVERAGE(C7:J7) -> 0.45025276 | M7: =VLOOKUP(A7,RANKING!A:C,3,0) -> 7 | Q7: =IF(C7>=50%,1,0) -> 1 | R7: =IF(D7>=50%,1,0) -> 1 | S7: =IF(E7>=50%,1,0) -> 1 | T7: =IF(F7>=50%,1,0) -> 0 | U7: =IF(G7>=50%,1,0) -> 0 | V7: =IF(H7>=50%,1,0) -> 0 | W7: =IF(I7>=50%,1,0) -> 0 | X7: =IF(J7>=50%,1,0) -> 0 | Y7: =IF(K7>=50%,1,0) -> 0 | Z7: =SUM(Q7:Y7) -> 3 | AA7: =IF(C7>=100%,1,0) -> 0 | AB7: =IF(D7>=100%,1,0) -> 0 | AC7: =IF(E7>=100%,1,0) -> 0 | AD7: =IF(F7>=100%,1,0) -> 0 | AE7: =IF(G7>=100%,1,0) -> 0 | AF7: =IF(H7>=100%,1,0) -> 0 | AG7: =IF(I7>=100%,1,0) -> 0 | AH7: =IF(J7>=100%,1,0) -> 0 | AI7: =IF(K7>=100%,1,0) -> 0 | AJ7: =SUM(AA7:AI7) -> 0
A8: 420 | B8: CINTIA RIZZI | C8: =VLOOKUP(A8,INCENTIVO!A:E,5,0) -> 0.42857143 | D8: =VLOOKUP(A8,INCENTIVO!A:H,8,0) -> 0.53333333 | E8: =VLOOKUP(A8,INCENTIVO!A:K,11,0) -> 0.3125 | F8: =VLOOKUP(A8,INCENTIVO!A:N,14,0) -> 0.0625 | G8: =VLOOKUP(A8,INCENTIVO!A:Q,17,0) -> 0 | H8: =VLOOKUP(A8,INCENTIVO!A:T,20,0) -> 0.43478261 | I8: =VLOOKUP(A8,INCENTIVO!A:W,23,0) -> 0.35294118 | J8: =VLOOKUP(A8,INCENTIVO!A:Z,26,0) -> 0.11613561 | K8: =VLOOKUP(A8,INCENTIVO!A:AC,29,0) -> 0.30769231 | L8: =AVERAGE(C8:J8) -> 0.28009552 | M8: =VLOOKUP(A8,RANKING!A:C,3,0) -> 27 | Q8: =IF(C8>=50%,1,0) -> 0 | R8: =IF(D8>=50%,1,0) -> 1 | S8: =IF(E8>=50%,1,0) -> 0 | T8: =IF(F8>=50%,1,0) -> 0 | U8: =IF(G8>=50%,1,0) -> 0 | V8: =IF(H8>=50%,1,0) -> 0 | W8: =IF(I8>=50%,1,0) -> 0 | X8: =IF(J8>=50%,1,0) -> 0 | Y8: =IF(K8>=50%,1,0) -> 0 | Z8: =SUM(Q8:Y8) -> 1 | AA8: =IF(C8>=100%,1,0) -> 0 | AB8: =IF(D8>=100%,1,0) -> 0 | AC8: =IF(E8>=100%,1,0) -> 0 | AD8: =IF(F8>=100%,1,0) -> 0 | AE8: =IF(G8>=100%,1,0) -> 0 | AF8: =IF(H8>=100%,1,0) -> 0 | AG8: =IF(I8>=100%,1,0) -> 0 | AH8: =IF(J8>=100%,1,0) -> 0 | AI8: =IF(K8>=100%,1,0) -> 0 | AJ8: =SUM(AA8:AI8) -> 0
A9: 410 | B9: GARCIA LARA | C9: =VLOOKUP(A9,INCENTIVO!A:E,5,0) -> 0.076923077 | D9: =VLOOKUP(A9,INCENTIVO!A:H,8,0) -> 0.35714286 | E9: =VLOOKUP(A9,INCENTIVO!A:K,11,0) -> 0.2 | F9: =VLOOKUP(A9,INCENTIVO!A:N,14,0) -> 0 | G9: =VLOOKUP(A9,INCENTIVO!A:Q,17,0) -> 0 | H9: =VLOOKUP(A9,INCENTIVO!A:T,20,0) -> 0.23809524 | I9: =VLOOKUP(A9,INCENTIVO!A:W,23,0) -> 0.13333333 | J9: =VLOOKUP(A9,INCENTIVO!A:Z,26,0) -> 0.090921261 | K9: =VLOOKUP(A9,INCENTIVO!A:AC,29,0) -> 0.090909091 | L9: =AVERAGE(C9:J9) -> 0.13705197 | M9: =VLOOKUP(A9,RANKING!A:C,3,0) -> 64 | O9: Ranking: | Q9: =IF(C9>=50%,1,0) -> 0 | R9: =IF(D9>=50%,1,0) -> 0 | S9: =IF(E9>=50%,1,0) -> 0 | T9: =IF(F9>=50%,1,0) -> 0 | U9: =IF(G9>=50%,1,0) -> 0 | V9: =IF(H9>=50%,1,0) -> 0 | W9: =IF(I9>=50%,1,0) -> 0 | X9: =IF(J9>=50%,1,0) -> 0 | Y9: =IF(K9>=50%,1,0) -> 0 | Z9: =SUM(Q9:Y9) -> 0 | AA9: =IF(C9>=100%,1,0) -> 0 | AB9: =IF(D9>=100%,1,0) -> 0 | AC9: =IF(E9>=100%,1,0) -> 0 | AD9: =IF(F9>=100%,1,0) -> 0 | AE9: =IF(G9>=100%,1,0) -> 0 | AF9: =IF(H9>=100%,1,0) -> 0 | AG9: =IF(I9>=100%,1,0) -> 0 | AH9: =IF(J9>=100%,1,0) -> 0 | AI9: =IF(K9>=100%,1,0) -> 0 | AJ9: =SUM(AA9:AI9) -> 0
A10: 456 | B10: BENITEZ MONICA | C10: =VLOOKUP(A10,INCENTIVO!A:E,5,0) -> 0.18181818 | D10: =VLOOKUP(A10,INCENTIVO!A:H,8,0) -> 0.58333333 | E10: =VLOOKUP(A10,INCENTIVO!A:K,11,0) -> 0.15384615 | F10: =VLOOKUP(A10,INCENTIVO!A:N,14,0) -> 0 | G10: =VLOOKUP(A10,INCENTIVO!A:Q,17,0) -> 0.1 | H10: =VLOOKUP(A10,INCENTIVO!A:T,20,0) -> 0.11111111 | I10: =VLOOKUP(A10,INCENTIVO!A:W,23,0) -> 0.071428571 | J10: =VLOOKUP(A10,INCENTIVO!A:Z,26,0) -> 0.10496633 | K10: =VLOOKUP(A10,INCENTIVO!A:AC,29,0) -> 0.1 | L10: =AVERAGE(C10:J10) -> 0.16331296 | M10: =VLOOKUP(A10,RANKING!A:C,3,0) -> 53 | O10: 15 primeros puestos $100.000 | Q10: =IF(C10>=50%,1,0) -> 0 | R10: =IF(D10>=50%,1,0) -> 1 | S10: =IF(E10>=50%,1,0) -> 0 | T10: =IF(F10>=50%,1,0) -> 0 | U10: =IF(G10>=50%,1,0) -> 0 | V10: =IF(H10>=50%,1,0) -> 0 | W10: =IF(I10>=50%,1,0) -> 0 | X10: =IF(J10>=50%,1,0) -> 0 | Y10: =IF(K10>=50%,1,0) -> 0 | Z10: =SUM(Q10:Y10) -> 1 | AA10: =IF(C10>=100%,1,0) -> 0 | AB10: =IF(D10>=100%,1,0) -> 0 | AC10: =IF(E10>=100%,1,0) -> 0 | AD10: =IF(F10>=100%,1,0) -> 0 | AE10: =IF(G10>=100%,1,0) -> 0 | AF10: =IF(H10>=100%,1,0) -> 0 | AG10: =IF(I10>=100%,1,0) -> 0 | AH10: =IF(J10>=100%,1,0) -> 0 | AI10: =IF(K10>=100%,1,0) -> 0 | AJ10: =SUM(AA10:AI10) -> 0
A11: Zona 350 | B11: Adriana Rodriguez | C11: =VLOOKUP(A11,INCENTIVO!A:E,5,0) -> 0.31132075 | D11: =VLOOKUP(A11,INCENTIVO!A:H,8,0) -> 0.59292035 | E11: =VLOOKUP(A11,INCENTIVO!A:K,11,0) -> 0.3 | F11: =VLOOKUP(A11,INCENTIVO!A:N,14,0) -> 0.083333333 | G11: =VLOOKUP(A11,INCENTIVO!A:Q,17,0) -> 0.086021505 | H11: =VLOOKUP(A11,INCENTIVO!A:T,20,0) -> 0.22941176 | I11: =VLOOKUP(A11,INCENTIVO!A:W,23,0) -> 0.18110236 | J11: =VLOOKUP(A11,INCENTIVO!A:Z,26,0) -> 0.16668097 | K11: =VLOOKUP(A11,INCENTIVO!A:AC,29,0) -> 0.25806452 | L11: =AVERAGE(C11:J11) -> 0.24384888 | O11: Promedio mayor a 100% | Q11: =IF(C11>=50%,1,0) -> 0 | R11: =IF(D11>=50%,1,0) -> 1 | S11: =IF(E11>=50%,1,0) -> 0 | T11: =IF(F11>=50%,1,0) -> 0 | U11: =IF(G11>=50%,1,0) -> 0 | V11: =IF(H11>=50%,1,0) -> 0 | W11: =IF(I11>=50%,1,0) -> 0 | X11: =IF(J11>=50%,1,0) -> 0 | Y11: =IF(K11>=50%,1,0) -> 0 | Z11: =SUM(Q11:Y11) -> 1 | AA11: =IF(C11>=100%,1,0) -> 0 | AB11: =IF(D11>=100%,1,0) -> 0 | AC11: =IF(E11>=100%,1,0) -> 0 | AD11: =IF(F11>=100%,1,0) -> 0 | AE11: =IF(G11>=100%,1,0) -> 0 | AF11: =IF(H11>=100%,1,0) -> 0 | AG11: =IF(I11>=100%,1,0) -> 0 | AH11: =IF(J11>=100%,1,0) -> 0 | AI11: =IF(K11>=100%,1,0) -> 0 | AJ11: =SUM(AA11:AI11) -> 0
A12: 421 | B12: MINONI GABRIEL DARIO | C12: =VLOOKUP(A12,INCENTIVO!A:E,5,0) -> 0.23076923 | D12: =VLOOKUP(A12,INCENTIVO!A:H,8,0) -> 0.14285714 | E12: =VLOOKUP(A12,INCENTIVO!A:K,11,0) -> 0.066666667 | F12: =VLOOKUP(A12,INCENTIVO!A:N,14,0) -> 0 | G12: =VLOOKUP(A12,INCENTIVO!A:Q,17,0) -> 0.090909091 | H12: =VLOOKUP(A12,INCENTIVO!A:T,20,0) -> 0.38095238 | I12: =VLOOKUP(A12,INCENTIVO!A:W,23,0) -> 0.066666667 | J12: =VLOOKUP(A12,INCENTIVO!A:Z,26,0) -> 0.15053959 | K12: =VLOOKUP(A12,INCENTIVO!A:AC,29,0) -> 0.36363636 | L12: =AVERAGE(C12:J12) -> 0.1411701 | M12: =VLOOKUP(A12,RANKING!A:C,3,0) -> 61 | Q12: =IF(C12>=50%,1,0) -> 0 | R12: =IF(D12>=50%,1,0) -> 0 | S12: =IF(E12>=50%,1,0) -> 0 | T12: =IF(F12>=50%,1,0) -> 0 | U12: =IF(G12>=50%,1,0) -> 0 | V12: =IF(H12>=50%,1,0) -> 0 | W12: =IF(I12>=50%,1,0) -> 0 | X12: =IF(J12>=50%,1,0) -> 0 | Y12: =IF(K12>=50%,1,0) -> 0 | Z12: =SUM(Q12:Y12) -> 0 | AA12: =IF(C12>=100%,1,0) -> 0 | AB12: =IF(D12>=100%,1,0) -> 0 | AC12: =IF(E12>=100%,1,0) -> 0 | AD12: =IF(F12>=100%,1,0) -> 0 | AE12: =IF(G12>=100%,1,0) -> 0 | AF12: =IF(H12>=100%,1,0) -> 0 | AG12: =IF(I12>=100%,1,0) -> 0 | AH12: =IF(J12>=100%,1,0) -> 0 | AI12: =IF(K12>=100%,1,0) -> 0 | AJ12: =SUM(AA12:AI12) -> 0
A13: 302 | B13: MARTINEZ DIEGO MAXIMILIANO | C13: =VLOOKUP(A13,INCENTIVO!A:E,5,0) -> 0.29411765 | D13: =VLOOKUP(A13,INCENTIVO!A:H,8,0) -> 0.38888889 | E13: =VLOOKUP(A13,INCENTIVO!A:K,11,0) -> 0.42105263 | F13: =VLOOKUP(A13,INCENTIVO!A:N,14,0) -> 0 | G13: =VLOOKUP(A13,INCENTIVO!A:Q,17,0) -> 0 | H13: =VLOOKUP(A13,INCENTIVO!A:T,20,0) -> 0.33333333 | I13: =VLOOKUP(A13,INCENTIVO!A:W,23,0) -> 0.25 | J13: =VLOOKUP(A13,INCENTIVO!A:Z,26,0) -> 0.21946818 | K13: =VLOOKUP(A13,INCENTIVO!A:AC,29,0) -> 0.2 | L13: =AVERAGE(C13:J13) -> 0.23835759 | M13: =VLOOKUP(A13,RANKING!A:C,3,0) -> 33 | O13: UNIDADES = 1 CCC | Q13: =IF(C13>=50%,1,0) -> 0 | R13: =IF(D13>=50%,1,0) -> 0 | S13: =IF(E13>=50%,1,0) -> 0 | T13: =IF(F13>=50%,1,0) -> 0 | U13: =IF(G13>=50%,1,0) -> 0 | V13: =IF(H13>=50%,1,0) -> 0 | W13: =IF(I13>=50%,1,0) -> 0 | X13: =IF(J13>=50%,1,0) -> 0 | Y13: =IF(K13>=50%,1,0) -> 0 | Z13: =SUM(Q13:Y13) -> 0 | AA13: =IF(C13>=100%,1,0) -> 0 | AB13: =IF(D13>=100%,1,0) -> 0 | AC13: =IF(E13>=100%,1,0) -> 0 | AD13: =IF(F13>=100%,1,0) -> 0 | AE13: =IF(G13>=100%,1,0) -> 0 | AF13: =IF(H13>=100%,1,0) -> 0 | AG13: =IF(I13>=100%,1,0) -> 0 | AH13: =IF(J13>=100%,1,0) -> 0 | AI13: =IF(K13>=100%,1,0) -> 0 | AJ13: =SUM(AA13:AI13) -> 0
A14: 440 | B14: MARQUEZ PABLO SERGIO | C14: =VLOOKUP(A14,INCENTIVO!A:E,5,0) -> 0.071428571 | D14: =VLOOKUP(A14,INCENTIVO!A:H,8,0) -> 0.66666667 | E14: =VLOOKUP(A14,INCENTIVO!A:K,11,0) -> 0.25 | F14: =VLOOKUP(A14,INCENTIVO!A:N,14,0) -> 0 | G14: =VLOOKUP(A14,INCENTIVO!A:Q,17,0) -> 0 | H14: =VLOOKUP(A14,INCENTIVO!A:T,20,0) -> 0.17391304 | I14: =VLOOKUP(A14,INCENTIVO!A:W,23,0) -> 0.52941176 | J14: =VLOOKUP(A14,INCENTIVO!A:Z,26,0) -> 0.066215918 | K14: =VLOOKUP(A14,INCENTIVO!A:AC,29,0) -> 0.25 | L14: =AVERAGE(C14:J14) -> 0.2197045 | M14: =VLOOKUP(A14,RANKING!A:C,3,0) -> 36 | O14: Hileret = 18 unidades | Q14: =IF(C14>=50%,1,0) -> 0 | R14: =IF(D14>=50%,1,0) -> 1 | S14: =IF(E14>=50%,1,0) -> 0 | T14: =IF(F14>=50%,1,0) -> 0 | U14: =IF(G14>=50%,1,0) -> 0 | V14: =IF(H14>=50%,1,0) -> 0 | W14: =IF(I14>=50%,1,0) -> 1 | X14: =IF(J14>=50%,1,0) -> 0 | Y14: =IF(K14>=50%,1,0) -> 0 | Z14: =SUM(Q14:Y14) -> 2 | AA14: =IF(C14>=100%,1,0) -> 0 | AB14: =IF(D14>=100%,1,0) -> 0 | AC14: =IF(E14>=100%,1,0) -> 0 | AD14: =IF(F14>=100%,1,0) -> 0 | AE14: =IF(G14>=100%,1,0) -> 0 | AF14: =IF(H14>=100%,1,0) -> 0 | AG14: =IF(I14>=100%,1,0) -> 0 | AH14: =IF(J14>=100%,1,0) -> 0 | AI14: =IF(K14>=100%,1,0) -> 0 | AJ14: =SUM(AA14:AI14) -> 0
A15: 401 | B15: VILAQUI ALBERTO ENRIQUE | C15: =VLOOKUP(A15,INCENTIVO!A:E,5,0) -> 0.15384615 | D15: =VLOOKUP(A15,INCENTIVO!A:H,8,0) -> 0.53846154 | E15: =VLOOKUP(A15,INCENTIVO!A:K,11,0) -> 0.071428571 | F15: =VLOOKUP(A15,INCENTIVO!A:N,14,0) -> 0 | G15: =VLOOKUP(A15,INCENTIVO!A:Q,17,0) -> 0 | H15: =VLOOKUP(A15,INCENTIVO!A:T,20,0) -> 0.15 | I15: =VLOOKUP(A15,INCENTIVO!A:W,23,0) -> 0.26666667 | J15: =VLOOKUP(A15,INCENTIVO!A:Z,26,0) -> 0.20470057 | K15: =VLOOKUP(A15,INCENTIVO!A:AC,29,0) -> 0.18181818 | L15: =AVERAGE(C15:J15) -> 0.17313794 | M15: =VLOOKUP(A15,RANKING!A:C,3,0) -> 45 | O15: Elvive = 24 unidades | Q15: =IF(C15>=50%,1,0) -> 0 | R15: =IF(D15>=50%,1,0) -> 1 | S15: =IF(E15>=50%,1,0) -> 0 | T15: =IF(F15>=50%,1,0) -> 0 | U15: =IF(G15>=50%,1,0) -> 0 | V15: =IF(H15>=50%,1,0) -> 0 | W15: =IF(I15>=50%,1,0) -> 0 | X15: =IF(J15>=50%,1,0) -> 0 | Y15: =IF(K15>=50%,1,0) -> 0 | Z15: =SUM(Q15:Y15) -> 1 | AA15: =IF(C15>=100%,1,0) -> 0 | AB15: =IF(D15>=100%,1,0) -> 0 | AC15: =IF(E15>=100%,1,0) -> 0 | AD15: =IF(F15>=100%,1,0) -> 0 | AE15: =IF(G15>=100%,1,0) -> 0 | AF15: =IF(H15>=100%,1,0) -> 0 | AG15: =IF(I15>=100%,1,0) -> 0 | AH15: =IF(J15>=100%,1,0) -> 0 | AI15: =IF(K15>=100%,1,0) -> 0 | AJ15: =SUM(AA15:AI15) -> 0
A16: 422 | B16: MICELI ARNALDO | C16: =VLOOKUP(A16,INCENTIVO!A:E,5,0) -> 0 | D16: =VLOOKUP(A16,INCENTIVO!A:H,8,0) -> 0.53333333 | E16: =VLOOKUP(A16,INCENTIVO!A:K,11,0) -> 0.4375 | F16: =VLOOKUP(A16,INCENTIVO!A:N,14,0) -> 0.125 | G16: =VLOOKUP(A16,INCENTIVO!A:Q,17,0) -> 0.41666667 | H16: =VLOOKUP(A16,INCENTIVO!A:T,20,0) -> 0.59090909 | I16: =VLOOKUP(A16,INCENTIVO!A:W,23,0) -> 0.23529412 | J16: =VLOOKUP(A16,INCENTIVO!A:Z,26,0) -> 0.20321064 | K16: =VLOOKUP(A16,INCENTIVO!A:AC,29,0) -> 0.41666667 | L16: =AVERAGE(C16:J16) -> 0.31773923 | M16: =VLOOKUP(A16,RANKING!A:C,3,0) -> 20 | O16: Carefree - Siempre Libre = 18 unidades | Q16: =IF(C16>=50%,1,0) -> 0 | R16: =IF(D16>=50%,1,0) -> 1 | S16: =IF(E16>=50%,1,0) -> 0 | T16: =IF(F16>=50%,1,0) -> 0 | U16: =IF(G16>=50%,1,0) -> 0 | V16: =IF(H16>=50%,1,0) -> 1 | W16: =IF(I16>=50%,1,0) -> 0 | X16: =IF(J16>=50%,1,0) -> 0 | Y16: =IF(K16>=50%,1,0) -> 0 | Z16: =SUM(Q16:Y16) -> 2 | AA16: =IF(C16>=100%,1,0) -> 0 | AB16: =IF(D16>=100%,1,0) -> 0 | AC16: =IF(E16>=100%,1,0) -> 0 | AD16: =IF(F16>=100%,1,0) -> 0 | AE16: =IF(G16>=100%,1,0) -> 0 | AF16: =IF(H16>=100%,1,0) -> 0 | AG16: =IF(I16>=100%,1,0) -> 0 | AH16: =IF(J16>=100%,1,0) -> 0 | AI16: =IF(K16>=100%,1,0) -> 0 | AJ16: =SUM(AA16:AI16) -> 0
A17: 470 | B17: DELBON GERARDO | C17: =VLOOKUP(A17,INCENTIVO!A:E,5,0) -> 0 | D17: =VLOOKUP(A17,INCENTIVO!A:H,8,0) -> 0.61538462 | E17: =VLOOKUP(A17,INCENTIVO!A:K,11,0) -> 0.21428571 | F17: =VLOOKUP(A17,INCENTIVO!A:N,14,0) -> 0 | G17: =VLOOKUP(A17,INCENTIVO!A:Q,17,0) -> 0 | H17: =VLOOKUP(A17,INCENTIVO!A:T,20,0) -> 0.5 | I17: =VLOOKUP(A17,INCENTIVO!A:W,23,0) -> 0.26666667 | J17: =VLOOKUP(A17,INCENTIVO!A:Z,26,0) -> 0.76800203 | K17: =VLOOKUP(A17,INCENTIVO!A:AC,29,0) -> 0.45454545 | L17: =AVERAGE(C17:J17) -> 0.29554238 | M17: =VLOOKUP(A17,RANKING!A:C,3,0) -> 23 | O17: 12U Calipso y 6U Nosotras | Q17: =IF(C17>=50%,1,0) -> 0 | R17: =IF(D17>=50%,1,0) -> 1 | S17: =IF(E17>=50%,1,0) -> 0 | T17: =IF(F17>=50%,1,0) -> 0 | U17: =IF(G17>=50%,1,0) -> 0 | V17: =IF(H17>=50%,1,0) -> 1 | W17: =IF(I17>=50%,1,0) -> 0 | X17: =IF(J17>=50%,1,0) -> 1 | Y17: =IF(K17>=50%,1,0) -> 0 | Z17: =SUM(Q17:Y17) -> 3 | AA17: =IF(C17>=100%,1,0) -> 0 | AB17: =IF(D17>=100%,1,0) -> 0 | AC17: =IF(E17>=100%,1,0) -> 0 | AD17: =IF(F17>=100%,1,0) -> 0 | AE17: =IF(G17>=100%,1,0) -> 0 | AF17: =IF(H17>=100%,1,0) -> 0 | AG17: =IF(I17>=100%,1,0) -> 0 | AH17: =IF(J17>=100%,1,0) -> 0 | AI17: =IF(K17>=100%,1,0) -> 0 | AJ17: =SUM(AA17:AI17) -> 0
A18: 423 | B18: SOLA DANIEL DANIEL | C18: =VLOOKUP(A18,INCENTIVO!A:E,5,0) -> 0.33333333 | D18: =VLOOKUP(A18,INCENTIVO!A:H,8,0) -> 0.5625 | E18: =VLOOKUP(A18,INCENTIVO!A:K,11,0) -> 0.47058824 | F18: =VLOOKUP(A18,INCENTIVO!A:N,14,0) -> 0.29411765 | G18: =VLOOKUP(A18,INCENTIVO!A:Q,17,0) -> 0.076923077 | H18: =VLOOKUP(A18,INCENTIVO!A:T,20,0) -> 0.54166667 | I18: =VLOOKUP(A18,INCENTIVO!A:W,23,0) -> 0.5 | J18: =VLOOKUP(A18,INCENTIVO!A:Z,26,0) -> 0.064654243 | K18: =VLOOKUP(A18,INCENTIVO!A:AC,29,0) -> 0.23076923 | L18: =AVERAGE(C18:J18) -> 0.3554729 | M18: =VLOOKUP(A18,RANKING!A:C,3,0) -> 10 | O18: Elegante = 24 unidades | Q18: =IF(C18>=50%,1,0) -> 0 | R18: =IF(D18>=50%,1,0) -> 1 | S18: =IF(E18>=50%,1,0) -> 0 | T18: =IF(F18>=50%,1,0) -> 0 | U18: =IF(G18>=50%,1,0) -> 0 | V18: =IF(H18>=50%,1,0) -> 1 | W18: =IF(I18>=50%,1,0) -> 1 | X18: =IF(J18>=50%,1,0) -> 0 | Y18: =IF(K18>=50%,1,0) -> 0 | Z18: =SUM(Q18:Y18) -> 3 | AA18: =IF(C18>=100%,1,0) -> 0 | AB18: =IF(D18>=100%,1,0) -> 0 | AC18: =IF(E18>=100%,1,0) -> 0 | AD18: =IF(F18>=100%,1,0) -> 0 | AE18: =IF(G18>=100%,1,0) -> 0 | AF18: =IF(H18>=100%,1,0) -> 0 | AG18: =IF(I18>=100%,1,0) -> 0 | AH18: =IF(J18>=100%,1,0) -> 0 | AI18: =IF(K18>=100%,1,0) -> 0 | AJ18: =SUM(AA18:AI18) -> 0
A19: 445 | B19: DI PRIETO DIEGO | C19: =VLOOKUP(A19,INCENTIVO!A:E,5,0) -> 0.13333333 | D19: =VLOOKUP(A19,INCENTIVO!A:H,8,0) -> 0.1875 | E19: =VLOOKUP(A19,INCENTIVO!A:K,11,0) -> 0.058823529 | F19: =VLOOKUP(A19,INCENTIVO!A:N,14,0) -> 0 | G19: =VLOOKUP(A19,INCENTIVO!A:Q,17,0) -> 0 | H19: =VLOOKUP(A19,INCENTIVO!A:T,20,0) -> 0.2173913 | I19: =VLOOKUP(A19,INCENTIVO!A:W,23,0) -> 0.22222222 | J19: =VLOOKUP(A19,INCENTIVO!A:Z,26,0) -> 0.2346626 | K19: =VLOOKUP(A19,INCENTIVO!A:AC,29,0) -> 0.076923077 | L19: =AVERAGE(C19:J19) -> 0.13174162 | M19: =VLOOKUP(A19,RANKING!A:C,3,0) -> 69 | O19: Cif = 24 unidades | Q19: =IF(C19>=50%,1,0) -> 0 | R19: =IF(D19>=50%,1,0) -> 0 | S19: =IF(E19>=50%,1,0) -> 0 | T19: =IF(F19>=50%,1,0) -> 0 | U19: =IF(G19>=50%,1,0) -> 0 | V19: =IF(H19>=50%,1,0) -> 0 | W19: =IF(I19>=50%,1,0) -> 0 | X19: =IF(J19>=50%,1,0) -> 0 | Y19: =IF(K19>=50%,1,0) -> 0 | Z19: =SUM(Q19:Y19) -> 0 | AA19: =IF(C19>=100%,1,0) -> 0 | AB19: =IF(D19>=100%,1,0) -> 0 | AC19: =IF(E19>=100%,1,0) -> 0 | AD19: =IF(F19>=100%,1,0) -> 0 | AE19: =IF(G19>=100%,1,0) -> 0 | AF19: =IF(H19>=100%,1,0) -> 0 | AG19: =IF(I19>=100%,1,0) -> 0 | AH19: =IF(J19>=100%,1,0) -> 0 | AI19: =IF(K19>=100%,1,0) -> 0 | AJ19: =SUM(AA19:AI19) -> 0
A20: 490 | B20: NUÑEZ ANDRES | C20: =VLOOKUP(A20,INCENTIVO!A:E,5,0) -> 0 | D20: =VLOOKUP(A20,INCENTIVO!A:H,8,0) -> 0.38461538 | E20: =VLOOKUP(A20,INCENTIVO!A:K,11,0) -> 0.076923077 | F20: =VLOOKUP(A20,INCENTIVO!A:N,14,0) -> 0 | G20: =VLOOKUP(A20,INCENTIVO!A:Q,17,0) -> 0.1 | H20: =VLOOKUP(A20,INCENTIVO!A:T,20,0) -> 0.31578947 | I20: =VLOOKUP(A20,INCENTIVO!A:W,23,0) -> 0.35714286 | J20: =VLOOKUP(A20,INCENTIVO!A:Z,26,0) -> 0.27649995 | K20: =VLOOKUP(A20,INCENTIVO!A:AC,29,0) -> 0 | L20: =AVERAGE(C20:J20) -> 0.18887134 | M20: =VLOOKUP(A20,RANKING!A:C,3,0) -> 41 | O20: Arlistan - Cruz Malta = 48 unidades | Q20: =IF(C20>=50%,1,0) -> 0 | R20: =IF(D20>=50%,1,0) -> 0 | S20: =IF(E20>=50%,1,0) -> 0 | T20: =IF(F20>=50%,1,0) -> 0 | U20: =IF(G20>=50%,1,0) -> 0 | V20: =IF(H20>=50%,1,0) -> 0 | W20: =IF(I20>=50%,1,0) -> 0 | X20: =IF(J20>=50%,1,0) -> 0 | Y20: =IF(K20>=50%,1,0) -> 0 | Z20: =SUM(Q20:Y20) -> 0 | AA20: =IF(C20>=100%,1,0) -> 0 | AB20: =IF(D20>=100%,1,0) -> 0 | AC20: =IF(E20>=100%,1,0) -> 0 | AD20: =IF(F20>=100%,1,0) -> 0 | AE20: =IF(G20>=100%,1,0) -> 0 | AF20: =IF(H20>=100%,1,0) -> 0 | AG20: =IF(I20>=100%,1,0) -> 0 | AH20: =IF(J20>=100%,1,0) -> 0 | AI20: =IF(K20>=100%,1,0) -> 0 | AJ20: =SUM(AA20:AI20) -> 0
A21: Zona 750 | B21: Oscar Lavalle | C21: =VLOOKUP(A21,INCENTIVO!A:E,5,0) -> 0.14285714 | D21: =VLOOKUP(A21,INCENTIVO!A:H,8,0) -> 0.44360902 | E21: =VLOOKUP(A21,INCENTIVO!A:K,11,0) -> 0.24113475 | F21: =VLOOKUP(A21,INCENTIVO!A:N,14,0) -> 0.04964539 | G21: =VLOOKUP(A21,INCENTIVO!A:Q,17,0) -> 0.074074074 | H21: =VLOOKUP(A21,INCENTIVO!A:T,20,0) -> 0.35678392 | I21: =VLOOKUP(A21,INCENTIVO!A:W,23,0) -> 0.040268456 | J21: =VLOOKUP(A21,INCENTIVO!A:Z,26,0) -> 0.207175 | K21: =VLOOKUP(A21,INCENTIVO!A:AC,29,0) -> 0.037037037 | L21: =AVERAGE(C21:J21) -> 0.19444347 | O21: Downy= 12 Unidades | Q21: =IF(C21>=50%,1,0) -> 0 | R21: =IF(D21>=50%,1,0) -> 0 | S21: =IF(E21>=50%,1,0) -> 0 | T21: =IF(F21>=50%,1,0) -> 0 | U21: =IF(G21>=50%,1,0) -> 0 | V21: =IF(H21>=50%,1,0) -> 0 | W21: =IF(I21>=50%,1,0) -> 0 | X21: =IF(J21>=50%,1,0) -> 0 | Y21: =IF(K21>=50%,1,0) -> 0 | Z21: =SUM(Q21:Y21) -> 0 | AA21: =IF(C21>=100%,1,0) -> 0 | AB21: =IF(D21>=100%,1,0) -> 0 | AC21: =IF(E21>=100%,1,0) -> 0 | AD21: =IF(F21>=100%,1,0) -> 0 | AE21: =IF(G21>=100%,1,0) -> 0 | AF21: =IF(H21>=100%,1,0) -> 0 | AG21: =IF(I21>=100%,1,0) -> 0 | AH21: =IF(J21>=100%,1,0) -> 0 | AI21: =IF(K21>=100%,1,0) -> 0 | AJ21: =SUM(AA21:AI21) -> 0
A22: 310 | B22: BENITEZ GUSTAVO FABIAN | C22: =VLOOKUP(A22,INCENTIVO!A:E,5,0) -> 0.23076923 | D22: =VLOOKUP(A22,INCENTIVO!A:H,8,0) -> 0.23076923 | E22: =VLOOKUP(A22,INCENTIVO!A:K,11,0) -> 0 | F22: =VLOOKUP(A22,INCENTIVO!A:N,14,0) -> 0 | G22: =VLOOKUP(A22,INCENTIVO!A:Q,17,0) -> 0 | H22: =VLOOKUP(A22,INCENTIVO!A:T,20,0) -> 0.15 | I22: =VLOOKUP(A22,INCENTIVO!A:W,23,0) -> 0.2 | J22: =VLOOKUP(A22,INCENTIVO!A:Z,26,0) -> 0.061652121 | K22: =VLOOKUP(A22,INCENTIVO!A:AC,29,0) -> 0.18181818 | L22: =AVERAGE(C22:J22) -> 0.10914882 | M22: =VLOOKUP(A22,RANKING!A:C,3,0) -> 82 | Q22: =IF(C22>=50%,1,0) -> 0 | R22: =IF(D22>=50%,1,0) -> 0 | S22: =IF(E22>=50%,1,0) -> 0 | T22: =IF(F22>=50%,1,0) -> 0 | U22: =IF(G22>=50%,1,0) -> 0 | V22: =IF(H22>=50%,1,0) -> 0 | W22: =IF(I22>=50%,1,0) -> 0 | X22: =IF(J22>=50%,1,0) -> 0 | Y22: =IF(K22>=50%,1,0) -> 0 | Z22: =SUM(Q22:Y22) -> 0 | AA22: =IF(C22>=100%,1,0) -> 0 | AB22: =IF(D22>=100%,1,0) -> 0 | AC22: =IF(E22>=100%,1,0) -> 0 | AD22: =IF(F22>=100%,1,0) -> 0 | AE22: =IF(G22>=100%,1,0) -> 0 | AF22: =IF(H22>=100%,1,0) -> 0 | AG22: =IF(I22>=100%,1,0) -> 0 | AH22: =IF(J22>=100%,1,0) -> 0 | AI22: =IF(K22>=100%,1,0) -> 0 | AJ22: =SUM(AA22:AI22) -> 0
A23: 351 | B23: LATTRECCHIANA SANTIAGO | C23: =VLOOKUP(A23,INCENTIVO!A:E,5,0) -> 0.16666667 | D23: =VLOOKUP(A23,INCENTIVO!A:H,8,0) -> 0.30769231 | E23: =VLOOKUP(A23,INCENTIVO!A:K,11,0) -> 0.076923077 | F23: =VLOOKUP(A23,INCENTIVO!A:N,14,0) -> 0 | G23: =VLOOKUP(A23,INCENTIVO!A:Q,17,0) -> 0.1 | H23: =VLOOKUP(A23,INCENTIVO!A:T,20,0) -> 0.36842105 | I23: =VLOOKUP(A23,INCENTIVO!A:W,23,0) -> 0.28571429 | J23: =VLOOKUP(A23,INCENTIVO!A:Z,26,0) -> 0.047525947 | K23: =VLOOKUP(A23,INCENTIVO!A:AC,29,0) -> 0.3 | L23: =AVERAGE(C23:J23) -> 0.16911792 | M23: =VLOOKUP(A23,RANKING!A:C,3,0) -> 47 | Q23: =IF(C23>=50%,1,0) -> 0 | R23: =IF(D23>=50%,1,0) -> 0 | S23: =IF(E23>=50%,1,0) -> 0 | T23: =IF(F23>=50%,1,0) -> 0 | U23: =IF(G23>=50%,1,0) -> 0 | V23: =IF(H23>=50%,1,0) -> 0 | W23: =IF(I23>=50%,1,0) -> 0 | X23: =IF(J23>=50%,1,0) -> 0 | Y23: =IF(K23>=50%,1,0) -> 0 | Z23: =SUM(Q23:Y23) -> 0 | AA23: =IF(C23>=100%,1,0) -> 0 | AB23: =IF(D23>=100%,1,0) -> 0 | AC23: =IF(E23>=100%,1,0) -> 0 | AD23: =IF(F23>=100%,1,0) -> 0 | AE23: =IF(G23>=100%,1,0) -> 0 | AF23: =IF(H23>=100%,1,0) -> 0 | AG23: =IF(I23>=100%,1,0) -> 0 | AH23: =IF(J23>=100%,1,0) -> 0 | AI23: =IF(K23>=100%,1,0) -> 0 | AJ23: =SUM(AA23:AI23) -> 0
A24: 311 | B24: BOIS DARIO EMILIO | C24: =VLOOKUP(A24,INCENTIVO!A:E,5,0) -> 0.125 | D24: =VLOOKUP(A24,INCENTIVO!A:H,8,0) -> 0.29411765 | E24: =VLOOKUP(A24,INCENTIVO!A:K,11,0) -> 0 | F24: =VLOOKUP(A24,INCENTIVO!A:N,14,0) -> 0 | G24: =VLOOKUP(A24,INCENTIVO!A:Q,17,0) -> 0 | H24: =VLOOKUP(A24,INCENTIVO!A:T,20,0) -> 0.30769231 | I24: =VLOOKUP(A24,INCENTIVO!A:W,23,0) -> 0.10526316 | J24: =VLOOKUP(A24,INCENTIVO!A:Z,26,0) -> 0.17936669 | K24: =VLOOKUP(A24,INCENTIVO!A:AC,29,0) -> 0 | L24: =AVERAGE(C24:J24) -> 0.12642997 | M24: =VLOOKUP(A24,RANKING!A:C,3,0) -> 75 | Q24: =IF(C24>=50%,1,0) -> 0 | R24: =IF(D24>=50%,1,0) -> 0 | S24: =IF(E24>=50%,1,0) -> 0 | T24: =IF(F24>=50%,1,0) -> 0 | U24: =IF(G24>=50%,1,0) -> 0 | V24: =IF(H24>=50%,1,0) -> 0 | W24: =IF(I24>=50%,1,0) -> 0 | X24: =IF(J24>=50%,1,0) -> 0 | Y24: =IF(K24>=50%,1,0) -> 0 | Z24: =SUM(Q24:Y24) -> 0 | AA24: =IF(C24>=100%,1,0) -> 0 | AB24: =IF(D24>=100%,1,0) -> 0 | AC24: =IF(E24>=100%,1,0) -> 0 | AD24: =IF(F24>=100%,1,0) -> 0 | AE24: =IF(G24>=100%,1,0) -> 0 | AF24: =IF(H24>=100%,1,0) -> 0 | AG24: =IF(I24>=100%,1,0) -> 0 | AH24: =IF(J24>=100%,1,0) -> 0 | AI24: =IF(K24>=100%,1,0) -> 0 | AJ24: =SUM(AA24:AI24) -> 0
A25: 312 | B25: AGUIRRE CESAR OSCAR | C25: =VLOOKUP(A25,INCENTIVO!A:E,5,0) -> 0.21428571 | D25: =VLOOKUP(A25,INCENTIVO!A:H,8,0) -> 0.46666667 | E25: =VLOOKUP(A25,INCENTIVO!A:K,11,0) -> 0.5625 | F25: =VLOOKUP(A25,INCENTIVO!A:N,14,0) -> 0.0625 | G25: =VLOOKUP(A25,INCENTIVO!A:Q,17,0) -> 0.083333333 | H25: =VLOOKUP(A25,INCENTIVO!A:T,20,0) -> 0.59090909 | I25: =VLOOKUP(A25,INCENTIVO!A:W,23,0) -> 0.47058824 | J25: =VLOOKUP(A25,INCENTIVO!A:Z,26,0) -> 0.29124141 | K25: =VLOOKUP(A25,INCENTIVO!A:AC,29,0) -> 0.33333333 | L25: =AVERAGE(C25:J25) -> 0.34275306 | M25: =VLOOKUP(A25,RANKING!A:C,3,0) -> 15 | Q25: =IF(C25>=50%,1,0) -> 0 | R25: =IF(D25>=50%,1,0) -> 0 | S25: =IF(E25>=50%,1,0) -> 1 | T25: =IF(F25>=50%,1,0) -> 0 | U25: =IF(G25>=50%,1,0) -> 0 | V25: =IF(H25>=50%,1,0) -> 1 | W25: =IF(I25>=50%,1,0) -> 0 | X25: =IF(J25>=50%,1,0) -> 0 | Y25: =IF(K25>=50%,1,0) -> 0 | Z25: =SUM(Q25:Y25) -> 2 | AA25: =IF(C25>=100%,1,0) -> 0 | AB25: =IF(D25>=100%,1,0) -> 0 | AC25: =IF(E25>=100%,1,0) -> 0 | AD25: =IF(F25>=100%,1,0) -> 0 | AE25: =IF(G25>=100%,1,0) -> 0 | AF25: =IF(H25>=100%,1,0) -> 0 | AG25: =IF(I25>=100%,1,0) -> 0 | AH25: =IF(J25>=100%,1,0) -> 0 | AI25: =IF(K25>=100%,1,0) -> 0 | AJ25: =SUM(AA25:AI25) -> 0
A26: 313 | B26: MAGALLANES JOSE | C26: =VLOOKUP(A26,INCENTIVO!A:E,5,0) -> 0.125 | D26: =VLOOKUP(A26,INCENTIVO!A:H,8,0) -> 0.52941176 | E26: =VLOOKUP(A26,INCENTIVO!A:K,11,0) -> 0.11111111 | F26: =VLOOKUP(A26,INCENTIVO!A:N,14,0) -> 0.27777778 | G26: =VLOOKUP(A26,INCENTIVO!A:Q,17,0) -> 0.071428571 | H26: =VLOOKUP(A26,INCENTIVO!A:T,20,0) -> 0.24 | I26: =VLOOKUP(A26,INCENTIVO!A:W,23,0) -> 0.10526316 | J26: =VLOOKUP(A26,INCENTIVO!A:Z,26,0) -> 0.18114039 | K26: =VLOOKUP(A26,INCENTIVO!A:AC,29,0) -> 0.35714286 | L26: =AVERAGE(C26:J26) -> 0.2051416 | M26: =VLOOKUP(A26,RANKING!A:C,3,0) -> 39 | Q26: =IF(C26>=50%,1,0) -> 0 | R26: =IF(D26>=50%,1,0) -> 1 | S26: =IF(E26>=50%,1,0) -> 0 | T26: =IF(F26>=50%,1,0) -> 0 | U26: =IF(G26>=50%,1,0) -> 0 | V26: =IF(H26>=50%,1,0) -> 0 | W26: =IF(I26>=50%,1,0) -> 0 | X26: =IF(J26>=50%,1,0) -> 0 | Y26: =IF(K26>=50%,1,0) -> 0 | Z26: =SUM(Q26:Y26) -> 1 | AA26: =IF(C26>=100%,1,0) -> 0 | AB26: =IF(D26>=100%,1,0) -> 0 | AC26: =IF(E26>=100%,1,0) -> 0 | AD26: =IF(F26>=100%,1,0) -> 0 | AE26: =IF(G26>=100%,1,0) -> 0 | AF26: =IF(H26>=100%,1,0) -> 0 | AG26: =IF(I26>=100%,1,0) -> 0 | AH26: =IF(J26>=100%,1,0) -> 0 | AI26: =IF(K26>=100%,1,0) -> 0 | AJ26: =SUM(AA26:AI26) -> 0
A27: 338 | B27: SARIA JAVIER | C27: =VLOOKUP(A27,INCENTIVO!A:E,5,0) -> 0.083333333 | D27: =VLOOKUP(A27,INCENTIVO!A:H,8,0) -> 0.69230769 | E27: =VLOOKUP(A27,INCENTIVO!A:K,11,0) -> 0.21428571 | F27: =VLOOKUP(A27,INCENTIVO!A:N,14,0) -> 0.21428571 | G27: =VLOOKUP(A27,INCENTIVO!A:Q,17,0) -> 0 | H27: =VLOOKUP(A27,INCENTIVO!A:T,20,0) -> 0.26315789 | I27: =VLOOKUP(A27,INCENTIVO!A:W,23,0) -> 0.33333333 | J27: =VLOOKUP(A27,INCENTIVO!A:Z,26,0) -> 0.87277205 | K27: =VLOOKUP(A27,INCENTIVO!A:AC,29,0) -> 0.45454545 | L27: =AVERAGE(C27:J27) -> 0.33418447 | M27: =VLOOKUP(A27,RANKING!A:C,3,0) -> 18 | Q27: =IF(C27>=50%,1,0) -> 0 | R27: =IF(D27>=50%,1,0) -> 1 | S27: =IF(E27>=50%,1,0) -> 0 | T27: =IF(F27>=50%,1,0) -> 0 | U27: =IF(G27>=50%,1,0) -> 0 | V27: =IF(H27>=50%,1,0) -> 0 | W27: =IF(I27>=50%,1,0) -> 0 | X27: =IF(J27>=50%,1,0) -> 1 | Y27: =IF(K27>=50%,1,0) -> 0 | Z27: =SUM(Q27:Y27) -> 2 | AA27: =IF(C27>=100%,1,0) -> 0 | AB27: =IF(D27>=100%,1,0) -> 0 | AC27: =IF(E27>=100%,1,0) -> 0 | AD27: =IF(F27>=100%,1,0) -> 0 | AE27: =IF(G27>=100%,1,0) -> 0 | AF27: =IF(H27>=100%,1,0) -> 0 | AG27: =IF(I27>=100%,1,0) -> 0 | AH27: =IF(J27>=100%,1,0) -> 0 | AI27: =IF(K27>=100%,1,0) -> 0 | AJ27: =SUM(AA27:AI27) -> 0
A28: 303 | B28: SEGOVIA KARINA | C28: =VLOOKUP(A28,INCENTIVO!A:E,5,0) -> 0.64285714 | D28: =VLOOKUP(A28,INCENTIVO!A:H,8,0) -> 0.66666667 | E28: =VLOOKUP(A28,INCENTIVO!A:K,11,0) -> 0.375 | F28: =VLOOKUP(A28,INCENTIVO!A:N,14,0) -> 0.4375 | G28: =VLOOKUP(A28,INCENTIVO!A:Q,17,0) -> 0.38461538 | H28: =VLOOKUP(A28,INCENTIVO!A:T,20,0) -> 0.60869565 | I28: =VLOOKUP(A28,INCENTIVO!A:W,23,0) -> 0.41176471 | J28: =VLOOKUP(A28,INCENTIVO!A:Z,26,0) -> 0.42413911 | K28: =VLOOKUP(A28,INCENTIVO!A:AC,29,0) -> 0.15384615 | L28: =AVERAGE(C28:J28) -> 0.49390483 | M28: =VLOOKUP(A28,RANKING!A:C,3,0) -> 5 | Q28: =IF(C28>=50%,1,0) -> 1 | R28: =IF(D28>=50%,1,0) -> 1 | S28: =IF(E28>=50%,1,0) -> 0 | T28: =IF(F28>=50%,1,0) -> 0 | U28: =IF(G28>=50%,1,0) -> 0 | V28: =IF(H28>=50%,1,0) -> 1 | W28: =IF(I28>=50%,1,0) -> 0 | X28: =IF(J28>=50%,1,0) -> 0 | Y28: =IF(K28>=50%,1,0) -> 0 | Z28: =SUM(Q28:Y28) -> 3 | AA28: =IF(C28>=100%,1,0) -> 0 | AB28: =IF(D28>=100%,1,0) -> 0 | AC28: =IF(E28>=100%,1,0) -> 0 | AD28: =IF(F28>=100%,1,0) -> 0 | AE28: =IF(G28>=100%,1,0) -> 0 | AF28: =IF(H28>=100%,1,0) -> 0 | AG28: =IF(I28>=100%,1,0) -> 0 | AH28: =IF(J28>=100%,1,0) -> 0 | AI28: =IF(K28>=100%,1,0) -> 0 | AJ28: =SUM(AA28:AI28) -> 0
A29: 354 | B29: AGUIRRE CARLOS ALBERTO | C29: =VLOOKUP(A29,INCENTIVO!A:E,5,0) -> 0.26666667 | D29: =VLOOKUP(A29,INCENTIVO!A:H,8,0) -> 0.75 | E29: =VLOOKUP(A29,INCENTIVO!A:K,11,0) -> 0.41176471 | F29: =VLOOKUP(A29,INCENTIVO!A:N,14,0) -> 0 | G29: =VLOOKUP(A29,INCENTIVO!A:Q,17,0) -> 0.076923077 | H29: =VLOOKUP(A29,INCENTIVO!A:T,20,0) -> 0.24 | I29: =VLOOKUP(A29,INCENTIVO!A:W,23,0) -> 0.16666667 | J29: =VLOOKUP(A29,INCENTIVO!A:Z,26,0) -> 0.14652736 | K29: =VLOOKUP(A29,INCENTIVO!A:AC,29,0) -> 0.38461538 | L29: =AVERAGE(C29:J29) -> 0.25731856 | M29: =VLOOKUP(A29,RANKING!A:C,3,0) -> 31 | Q29: =IF(C29>=50%,1,0) -> 0 | R29: =IF(D29>=50%,1,0) -> 1 | S29: =IF(E29>=50%,1,0) -> 0 | T29: =IF(F29>=50%,1,0) -> 0 | U29: =IF(G29>=50%,1,0) -> 0 | V29: =IF(H29>=50%,1,0) -> 0 | W29: =IF(I29>=50%,1,0) -> 0 | X29: =IF(J29>=50%,1,0) -> 0 | Y29: =IF(K29>=50%,1,0) -> 0 | Z29: =SUM(Q29:Y29) -> 1 | AA29: =IF(C29>=100%,1,0) -> 0 | AB29: =IF(D29>=100%,1,0) -> 0 | AC29: =IF(E29>=100%,1,0) -> 0 | AD29: =IF(F29>=100%,1,0) -> 0 | AE29: =IF(G29>=100%,1,0) -> 0 | AF29: =IF(H29>=100%,1,0) -> 0 | AG29: =IF(I29>=100%,1,0) -> 0 | AH29: =IF(J29>=100%,1,0) -> 0 | AI29: =IF(K29>=100%,1,0) -> 0 | AJ29: =SUM(AA29:AI29) -> 0
A30: 341 | B30: SOTO NICOLAS EZEQUIEL | C30: =VLOOKUP(A30,INCENTIVO!A:E,5,0) -> 0.61538462 | D30: =VLOOKUP(A30,INCENTIVO!A:H,8,0) -> 0.71428571 | E30: =VLOOKUP(A30,INCENTIVO!A:K,11,0) -> 0.53333333 | F30: =VLOOKUP(A30,INCENTIVO!A:N,14,0) -> 0.53333333 | G30: =VLOOKUP(A30,INCENTIVO!A:Q,17,0) -> 0.090909091 | H30: =VLOOKUP(A30,INCENTIVO!A:T,20,0) -> 0.57142857 | I30: =VLOOKUP(A30,INCENTIVO!A:W,23,0) -> 0.33333333 | J30: =VLOOKUP(A30,INCENTIVO!A:Z,26,0) -> 1.9247707 | K30: =VLOOKUP(A30,INCENTIVO!A:AC,29,0) -> 0.18181818 | L30: =AVERAGE(C30:J30) -> 0.66459733 | M30: =VLOOKUP(A30,RANKING!A:C,3,0) -> 2 | Q30: =IF(C30>=50%,1,0) -> 1 | R30: =IF(D30>=50%,1,0) -> 1 | S30: =IF(E30>=50%,1,0) -> 1 | T30: =IF(F30>=50%,1,0) -> 1 | U30: =IF(G30>=50%,1,0) -> 0 | V30: =IF(H30>=50%,1,0) -> 1 | W30: =IF(I30>=50%,1,0) -> 0 | X30: =IF(J30>=50%,1,0) -> 1 | Y30: =IF(K30>=50%,1,0) -> 0 | Z30: =SUM(Q30:Y30) -> 6 | AA30: =IF(C30>=100%,1,0) -> 0 | AB30: =IF(D30>=100%,1,0) -> 0 | AC30: =IF(E30>=100%,1,0) -> 0 | AD30: =IF(F30>=100%,1,0) -> 0 | AE30: =IF(G30>=100%,1,0) -> 0 | AF30: =IF(H30>=100%,1,0) -> 0 | AG30: =IF(I30>=100%,1,0) -> 0 | AH30: =IF(J30>=100%,1,0) -> 1 | AI30: =IF(K30>=100%,1,0) -> 0 | AJ30: =SUM(AA30:AI30) -> 1
A31: 314 | B31: BARRAUD PATRICIA | C31: =VLOOKUP(A31,INCENTIVO!A:E,5,0) -> 0.15384615 | D31: =VLOOKUP(A31,INCENTIVO!A:H,8,0) -> 0.38461538 | E31: =VLOOKUP(A31,INCENTIVO!A:K,11,0) -> 0 | F31: =VLOOKUP(A31,INCENTIVO!A:N,14,0) -> 0 | G31: =VLOOKUP(A31,INCENTIVO!A:Q,17,0) -> 0 | H31: =VLOOKUP(A31,INCENTIVO!A:T,20,0) -> 0.3 | I31: =VLOOKUP(A31,INCENTIVO!A:W,23,0) -> 0.13333333 | J31: =VLOOKUP(A31,INCENTIVO!A:Z,26,0) -> 0.25397353 | K31: =VLOOKUP(A31,INCENTIVO!A:AC,29,0) -> 0.090909091 | L31: =AVERAGE(C31:J31) -> 0.15322105 | M31: =VLOOKUP(A31,RANKING!A:C,3,0) -> 55 | Q31: =IF(C31>=50%,1,0) -> 0 | R31: =IF(D31>=50%,1,0) -> 0 | S31: =IF(E31>=50%,1,0) -> 0 | T31: =IF(F31>=50%,1,0) -> 0 | U31: =IF(G31>=50%,1,0) -> 0 | V31: =IF(H31>=50%,1,0) -> 0 | W31: =IF(I31>=50%,1,0) -> 0 | X31: =IF(J31>=50%,1,0) -> 0 | Y31: =IF(K31>=50%,1,0) -> 0 | Z31: =SUM(Q31:Y31) -> 0 | AA31: =IF(C31>=100%,1,0) -> 0 | AB31: =IF(D31>=100%,1,0) -> 0 | AC31: =IF(E31>=100%,1,0) -> 0 | AD31: =IF(F31>=100%,1,0) -> 0 | AE31: =IF(G31>=100%,1,0) -> 0 | AF31: =IF(H31>=100%,1,0) -> 0 | AG31: =IF(I31>=100%,1,0) -> 0 | AH31: =IF(J31>=100%,1,0) -> 0 | AI31: =IF(K31>=100%,1,0) -> 0 | AJ31: =SUM(AA31:AI31) -> 0
A32: Zona 800 | B32: Fabio Vazquez | C32: =VLOOKUP(A32,INCENTIVO!A:E,5,0) -> 0.26086957 | D32: =VLOOKUP(A32,INCENTIVO!A:H,8,0) -> 0.50684932 | E32: =VLOOKUP(A32,INCENTIVO!A:K,11,0) -> 0.23225806 | F32: =VLOOKUP(A32,INCENTIVO!A:N,14,0) -> 0.15483871 | G32: =VLOOKUP(A32,INCENTIVO!A:Q,17,0) -> 0.083333333 | H32: =VLOOKUP(A32,INCENTIVO!A:T,20,0) -> 0.36363636 | I32: =VLOOKUP(A32,INCENTIVO!A:W,23,0) -> 0.25 | J32: =VLOOKUP(A32,INCENTIVO!A:Z,26,0) -> 0.42291718 | K32: =VLOOKUP(A32,INCENTIVO!A:AC,29,0) -> 0.24166667 | L32: =AVERAGE(C32:J32) -> 0.28433782 | Q32: =IF(C32>=50%,1,0) -> 0 | R32: =IF(D32>=50%,1,0) -> 1 | S32: =IF(E32>=50%,1,0) -> 0 | T32: =IF(F32>=50%,1,0) -> 0 | U32: =IF(G32>=50%,1,0) -> 0 | V32: =IF(H32>=50%,1,0) -> 0 | W32: =IF(I32>=50%,1,0) -> 0 | X32: =IF(J32>=50%,1,0) -> 0 | Y32: =IF(K32>=50%,1,0) -> 0 | Z32: =SUM(Q32:Y32) -> 1 | AA32: =IF(C32>=100%,1,0) -> 0 | AB32: =IF(D32>=100%,1,0) -> 0 | AC32: =IF(E32>=100%,1,0) -> 0 | AD32: =IF(F32>=100%,1,0) -> 0 | AE32: =IF(G32>=100%,1,0) -> 0 | AF32: =IF(H32>=100%,1,0) -> 0 | AG32: =IF(I32>=100%,1,0) -> 0 | AH32: =IF(J32>=100%,1,0) -> 0 | AI32: =IF(K32>=100%,1,0) -> 0 | AJ32: =SUM(AA32:AI32) -> 0
A33: 315 | B33: PAZ TERESA | C33: =VLOOKUP(A33,INCENTIVO!A:E,5,0) -> 0.071428571 | D33: =VLOOKUP(A33,INCENTIVO!A:H,8,0) -> 0.53333333 | E33: =VLOOKUP(A33,INCENTIVO!A:K,11,0) -> 0.5625 | F33: =VLOOKUP(A33,INCENTIVO!A:N,14,0) -> 0 | G33: =VLOOKUP(A33,INCENTIVO!A:Q,17,0) -> 0.16666667 | H33: =VLOOKUP(A33,INCENTIVO!A:T,20,0) -> 0.54545455 | I33: =VLOOKUP(A33,INCENTIVO!A:W,23,0) -> 0.47058824 | J33: =VLOOKUP(A33,INCENTIVO!A:Z,26,0) -> 0.099425588 | K33: =VLOOKUP(A33,INCENTIVO!A:AC,29,0) -> 0.33333333 | L33: =AVERAGE(C33:J33) -> 0.30617462 | M33: =VLOOKUP(A33,RANKING!A:C,3,0) -> 21 | Q33: =IF(C33>=50%,1,0) -> 0 | R33: =IF(D33>=50%,1,0) -> 1 | S33: =IF(E33>=50%,1,0) -> 1 | T33: =IF(F33>=50%,1,0) -> 0 | U33: =IF(G33>=50%,1,0) -> 0 | V33: =IF(H33>=50%,1,0) -> 1 | W33: =IF(I33>=50%,1,0) -> 0 | X33: =IF(J33>=50%,1,0) -> 0 | Y33: =IF(K33>=50%,1,0) -> 0 | Z33: =SUM(Q33:Y33) -> 3 | AA33: =IF(C33>=100%,1,0) -> 0 | AB33: =IF(D33>=100%,1,0) -> 0 | AC33: =IF(E33>=100%,1,0) -> 0 | AD33: =IF(F33>=100%,1,0) -> 0 | AE33: =IF(G33>=100%,1,0) -> 0 | AF33: =IF(H33>=100%,1,0) -> 0 | AG33: =IF(I33>=100%,1,0) -> 0 | AH33: =IF(J33>=100%,1,0) -> 0 | AI33: =IF(K33>=100%,1,0) -> 0 | AJ33: =SUM(AA33:AI33) -> 0
A34: 316 | B34: CABELLO YURI CARMEN | C34: =VLOOKUP(A34,INCENTIVO!A:E,5,0) -> 0.42857143 | D34: =VLOOKUP(A34,INCENTIVO!A:H,8,0) -> 1 | E34: =VLOOKUP(A34,INCENTIVO!A:K,11,0) -> 0.5 | F34: =VLOOKUP(A34,INCENTIVO!A:N,14,0) -> 0.125 | G34: =VLOOKUP(A34,INCENTIVO!A:Q,17,0) -> 0 | H34: =VLOOKUP(A34,INCENTIVO!A:T,20,0) -> 0.77272727 | I34: =VLOOKUP(A34,INCENTIVO!A:W,23,0) -> 0.29411765 | J34: =VLOOKUP(A34,INCENTIVO!A:Z,26,0) -> 0.085234349 | K34: =VLOOKUP(A34,INCENTIVO!A:AC,29,0) -> 0.083333333 | L34: =AVERAGE(C34:J34) -> 0.40070634 | M34: =VLOOKUP(A34,RANKING!A:C,3,0) -> 8 | Q34: =IF(C34>=50%,1,0) -> 0 | R34: =IF(D34>=50%,1,0) -> 1 | S34: =IF(E34>=50%,1,0) -> 1 | T34: =IF(F34>=50%,1,0) -> 0 | U34: =IF(G34>=50%,1,0) -> 0 | V34: =IF(H34>=50%,1,0) -> 1 | W34: =IF(I34>=50%,1,0) -> 0 | X34: =IF(J34>=50%,1,0) -> 0 | Y34: =IF(K34>=50%,1,0) -> 0 | Z34: =SUM(Q34:Y34) -> 3 | AA34: =IF(C34>=100%,1,0) -> 0 | AB34: =IF(D34>=100%,1,0) -> 1 | AC34: =IF(E34>=100%,1,0) -> 0 | AD34: =IF(F34>=100%,1,0) -> 0 | AE34: =IF(G34>=100%,1,0) -> 0 | AF34: =IF(H34>=100%,1,0) -> 0 | AG34: =IF(I34>=100%,1,0) -> 0 | AH34: =IF(J34>=100%,1,0) -> 0 | AI34: =IF(K34>=100%,1,0) -> 0 | AJ34: =SUM(AA34:AI34) -> 1
A35: 317 | B35: CONFORTI FATIMA | C35: =VLOOKUP(A35,INCENTIVO!A:E,5,0) -> 0.6 | D35: =VLOOKUP(A35,INCENTIVO!A:H,8,0) -> 0.4375 | E35: =VLOOKUP(A35,INCENTIVO!A:K,11,0) -> 0.47058824 | F35: =VLOOKUP(A35,INCENTIVO!A:N,14,0) -> 0.11764706 | G35: =VLOOKUP(A35,INCENTIVO!A:Q,17,0) -> 0 | H35: =VLOOKUP(A35,INCENTIVO!A:T,20,0) -> 0.625 | I35: =VLOOKUP(A35,INCENTIVO!A:W,23,0) -> 0.33333333 | J35: =VLOOKUP(A35,INCENTIVO!A:Z,26,0) -> 0.23703498 | K35: =VLOOKUP(A35,INCENTIVO!A:AC,29,0) -> 0.38461538 | L35: =AVERAGE(C35:J35) -> 0.35263795 | M35: =VLOOKUP(A35,RANKING!A:C,3,0) -> 11 | Q35: =IF(C35>=50%,1,0) -> 1 | R35: =IF(D35>=50%,1,0) -> 0 | S35: =IF(E35>=50%,1,0) -> 0 | T35: =IF(F35>=50%,1,0) -> 0 | U35: =IF(G35>=50%,1,0) -> 0 | V35: =IF(H35>=50%,1,0) -> 1 | W35: =IF(I35>=50%,1,0) -> 0 | X35: =IF(J35>=50%,1,0) -> 0 | Y35: =IF(K35>=50%,1,0) -> 0 | Z35: =SUM(Q35:Y35) -> 2 | AA35: =IF(C35>=100%,1,0) -> 0 | AB35: =IF(D35>=100%,1,0) -> 0 | AC35: =IF(E35>=100%,1,0) -> 0 | AD35: =IF(F35>=100%,1,0) -> 0 | AE35: =IF(G35>=100%,1,0) -> 0 | AF35: =IF(H35>=100%,1,0) -> 0 | AG35: =IF(I35>=100%,1,0) -> 0 | AH35: =IF(J35>=100%,1,0) -> 0 | AI35: =IF(K35>=100%,1,0) -> 0 | AJ35: =SUM(AA35:AI35) -> 0
A36: 336 | B36: ALVAREZ MARTIN | C36: =VLOOKUP(A36,INCENTIVO!A:E,5,0) -> 0.30769231 | D36: =VLOOKUP(A36,INCENTIVO!A:H,8,0) -> 0.28571429 | E36: =VLOOKUP(A36,INCENTIVO!A:K,11,0) -> 0.066666667 | F36: =VLOOKUP(A36,INCENTIVO!A:N,14,0) -> 0 | G36: =VLOOKUP(A36,INCENTIVO!A:Q,17,0) -> 0 | H36: =VLOOKUP(A36,INCENTIVO!A:T,20,0) -> 0.28571429 | I36: =VLOOKUP(A36,INCENTIVO!A:W,23,0) -> 0.1875 | J36: =VLOOKUP(A36,INCENTIVO!A:Z,26,0) -> 0.31126888 | K36: =VLOOKUP(A36,INCENTIVO!A:AC,29,0) -> 0.25 | L36: =AVERAGE(C36:J36) -> 0.18056955 | M36: =VLOOKUP(A36,RANKING!A:C,3,0) -> 43 | Q36: =IF(C36>=50%,1,0) -> 0 | R36: =IF(D36>=50%,1,0) -> 0 | S36: =IF(E36>=50%,1,0) -> 0 | T36: =IF(F36>=50%,1,0) -> 0 | U36: =IF(G36>=50%,1,0) -> 0 | V36: =IF(H36>=50%,1,0) -> 0 | W36: =IF(I36>=50%,1,0) -> 0 | X36: =IF(J36>=50%,1,0) -> 0 | Y36: =IF(K36>=50%,1,0) -> 0 | Z36: =SUM(Q36:Y36) -> 0 | AA36: =IF(C36>=100%,1,0) -> 0 | AB36: =IF(D36>=100%,1,0) -> 0 | AC36: =IF(E36>=100%,1,0) -> 0 | AD36: =IF(F36>=100%,1,0) -> 0 | AE36: =IF(G36>=100%,1,0) -> 0 | AF36: =IF(H36>=100%,1,0) -> 0 | AG36: =IF(I36>=100%,1,0) -> 0 | AH36: =IF(J36>=100%,1,0) -> 0 | AI36: =IF(K36>=100%,1,0) -> 0 | AJ36: =SUM(AA36:AI36) -> 0
A37: 345 | B37: PEREZ LORENA SILVIA | C37: =VLOOKUP(A37,INCENTIVO!A:E,5,0) -> 0.13333333 | D37: =VLOOKUP(A37,INCENTIVO!A:H,8,0) -> 0.375 | E37: =VLOOKUP(A37,INCENTIVO!A:K,11,0) -> 0.17647059 | F37: =VLOOKUP(A37,INCENTIVO!A:N,14,0) -> 0 | G37: =VLOOKUP(A37,INCENTIVO!A:Q,17,0) -> 0 | H37: =VLOOKUP(A37,INCENTIVO!A:T,20,0) -> 0.25 | I37: =VLOOKUP(A37,INCENTIVO!A:W,23,0) -> 0 | J37: =VLOOKUP(A37,INCENTIVO!A:Z,26,0) -> 0.087687157 | K37: =VLOOKUP(A37,INCENTIVO!A:AC,29,0) -> 0.23076923 | L37: =AVERAGE(C37:J37) -> 0.12781138 | M37: =VLOOKUP(A37,RANKING!A:C,3,0) -> 73 | Q37: =IF(C37>=50%,1,0) -> 0 | R37: =IF(D37>=50%,1,0) -> 0 | S37: =IF(E37>=50%,1,0) -> 0 | T37: =IF(F37>=50%,1,0) -> 0 | U37: =IF(G37>=50%,1,0) -> 0 | V37: =IF(H37>=50%,1,0) -> 0 | W37: =IF(I37>=50%,1,0) -> 0 | X37: =IF(J37>=50%,1,0) -> 0 | Y37: =IF(K37>=50%,1,0) -> 0 | Z37: =SUM(Q37:Y37) -> 0 | AA37: =IF(C37>=100%,1,0) -> 0 | AB37: =IF(D37>=100%,1,0) -> 0 | AC37: =IF(E37>=100%,1,0) -> 0 | AD37: =IF(F37>=100%,1,0) -> 0 | AE37: =IF(G37>=100%,1,0) -> 0 | AF37: =IF(H37>=100%,1,0) -> 0 | AG37: =IF(I37>=100%,1,0) -> 0 | AH37: =IF(J37>=100%,1,0) -> 0 | AI37: =IF(K37>=100%,1,0) -> 0 | AJ37: =SUM(AA37:AI37) -> 0
A38: 375 | B38: RUIZ JULIANA | C38: =VLOOKUP(A38,INCENTIVO!A:E,5,0) -> 0.14285714 | D38: =VLOOKUP(A38,INCENTIVO!A:H,8,0) -> 0.8 | E38: =VLOOKUP(A38,INCENTIVO!A:K,11,0) -> 0.3125 | F38: =VLOOKUP(A38,INCENTIVO!A:N,14,0) -> 0.125 | G38: =VLOOKUP(A38,INCENTIVO!A:Q,17,0) -> 0.076923077 | H38: =VLOOKUP(A38,INCENTIVO!A:T,20,0) -> 0.34782609 | I38: =VLOOKUP(A38,INCENTIVO!A:W,23,0) -> 0.41176471 | J38: =VLOOKUP(A38,INCENTIVO!A:Z,26,0) -> 0.068045164 | K38: =VLOOKUP(A38,INCENTIVO!A:AC,29,0) -> 0.23076923 | L38: =AVERAGE(C38:J38) -> 0.28561452 | M38: =VLOOKUP(A38,RANKING!A:C,3,0) -> 24 | Q38: =IF(C38>=50%,1,0) -> 0 | R38: =IF(D38>=50%,1,0) -> 1 | S38: =IF(E38>=50%,1,0) -> 0 | T38: =IF(F38>=50%,1,0) -> 0 | U38: =IF(G38>=50%,1,0) -> 0 | V38: =IF(H38>=50%,1,0) -> 0 | W38: =IF(I38>=50%,1,0) -> 0 | X38: =IF(J38>=50%,1,0) -> 0 | Y38: =IF(K38>=50%,1,0) -> 0 | Z38: =SUM(Q38:Y38) -> 1 | AA38: =IF(C38>=100%,1,0) -> 0 | AB38: =IF(D38>=100%,1,0) -> 0 | AC38: =IF(E38>=100%,1,0) -> 0 | AD38: =IF(F38>=100%,1,0) -> 0 | AE38: =IF(G38>=100%,1,0) -> 0 | AF38: =IF(H38>=100%,1,0) -> 0 | AG38: =IF(I38>=100%,1,0) -> 0 | AH38: =IF(J38>=100%,1,0) -> 0 | AI38: =IF(K38>=100%,1,0) -> 0 | AJ38: =SUM(AA38:AI38) -> 0
A39: 361 | B39: VALENZUELA ALAN | C39: =VLOOKUP(A39,INCENTIVO!A:E,5,0) -> 0 | D39: =VLOOKUP(A39,INCENTIVO!A:H,8,0) -> 0.61538462 | E39: =VLOOKUP(A39,INCENTIVO!A:K,11,0) -> 0.14285714 | F39: =VLOOKUP(A39,INCENTIVO!A:N,14,0) -> 0 | G39: =VLOOKUP(A39,INCENTIVO!A:Q,17,0) -> 0 | H39: =VLOOKUP(A39,INCENTIVO!A:T,20,0) -> 0.15 | I39: =VLOOKUP(A39,INCENTIVO!A:W,23,0) -> 0.13333333 | J39: =VLOOKUP(A39,INCENTIVO!A:Z,26,0) -> 0.15580207 | K39: =VLOOKUP(A39,INCENTIVO!A:AC,29,0) -> 0.18181818 | L39: =AVERAGE(C39:J39) -> 0.14967215 | M39: =VLOOKUP(A39,RANKING!A:C,3,0) -> 57 | Q39: =IF(C39>=50%,1,0) -> 0 | R39: =IF(D39>=50%,1,0) -> 1 | S39: =IF(E39>=50%,1,0) -> 0 | T39: =IF(F39>=50%,1,0) -> 0 | U39: =IF(G39>=50%,1,0) -> 0 | V39: =IF(H39>=50%,1,0) -> 0 | W39: =IF(I39>=50%,1,0) -> 0 | X39: =IF(J39>=50%,1,0) -> 0 | Y39: =IF(K39>=50%,1,0) -> 0 | Z39: =SUM(Q39:Y39) -> 1 | AA39: =IF(C39>=100%,1,0) -> 0 | AB39: =IF(D39>=100%,1,0) -> 0 | AC39: =IF(E39>=100%,1,0) -> 0 | AD39: =IF(F39>=100%,1,0) -> 0 | AE39: =IF(G39>=100%,1,0) -> 0 | AF39: =IF(H39>=100%,1,0) -> 0 | AG39: =IF(I39>=100%,1,0) -> 0 | AH39: =IF(J39>=100%,1,0) -> 0 | AI39: =IF(K39>=100%,1,0) -> 0 | AJ39: =SUM(AA39:AI39) -> 0
A40: 370 | B40: SEISDEDOS TAMARA | C40: =VLOOKUP(A40,INCENTIVO!A:E,5,0) -> 0.36363636 | D40: =VLOOKUP(A40,INCENTIVO!A:H,8,0) -> 1.0833333 | E40: =VLOOKUP(A40,INCENTIVO!A:K,11,0) -> 0.30769231 | F40: =VLOOKUP(A40,INCENTIVO!A:N,14,0) -> 0.076923077 | G40: =VLOOKUP(A40,INCENTIVO!A:Q,17,0) -> 0 | H40: =VLOOKUP(A40,INCENTIVO!A:T,20,0) -> 0.38888889 | I40: =VLOOKUP(A40,INCENTIVO!A:W,23,0) -> 0.23076923 | J40: =VLOOKUP(A40,INCENTIVO!A:Z,26,0) -> 0.29612861 | K40: =VLOOKUP(A40,INCENTIVO!A:AC,29,0) -> 0.2 | L40: =AVERAGE(C40:J40) -> 0.34342148 | M40: =VLOOKUP(A40,RANKING!A:C,3,0) -> 14 | Q40: =IF(C40>=50%,1,0) -> 0 | R40: =IF(D40>=50%,1,0) -> 1 | S40: =IF(E40>=50%,1,0) -> 0 | T40: =IF(F40>=50%,1,0) -> 0 | U40: =IF(G40>=50%,1,0) -> 0 | V40: =IF(H40>=50%,1,0) -> 0 | W40: =IF(I40>=50%,1,0) -> 0 | X40: =IF(J40>=50%,1,0) -> 0 | Y40: =IF(K40>=50%,1,0) -> 0 | Z40: =SUM(Q40:Y40) -> 1 | AA40: =IF(C40>=100%,1,0) -> 0 | AB40: =IF(D40>=100%,1,0) -> 1 | AC40: =IF(E40>=100%,1,0) -> 0 | AD40: =IF(F40>=100%,1,0) -> 0 | AE40: =IF(G40>=100%,1,0) -> 0 | AF40: =IF(H40>=100%,1,0) -> 0 | AG40: =IF(I40>=100%,1,0) -> 0 | AH40: =IF(J40>=100%,1,0) -> 0 | AI40: =IF(K40>=100%,1,0) -> 0 | AJ40: =SUM(AA40:AI40) -> 1
...

Sheet RANKING
A1: N° de Ruta | B1: PROMEDIO | C1: Ranking
A2: 131 | B2: =VLOOKUP(A2,GRILLA!A:M,12,0) -> 1.0067748 | C2: =RANK(B2,$B$2:$B$97) -> 1
A3: 341 | B3: =VLOOKUP(A3,GRILLA!A:M,12,0) -> 0.66459733 | C3: =RANK(B3,$B$2:$B$97) -> 2
A4: 386 | B4: =VLOOKUP(A4,GRILLA!A:M,12,0) -> 0.62808992 | C4: =RANK(B4,$B$2:$B$97) -> 3
A5: 140 | B5: =VLOOKUP(A5,GRILLA!A:M,12,0) -> 0.56184315 | C5: =RANK(B5,$B$2:$B$97) -> 4
A6: 303 | B6: =VLOOKUP(A6,GRILLA!A:M,12,0) -> 0.49390483 | C6: =RANK(B6,$B$2:$B$97) -> 5
A7: 102 | B7: =VLOOKUP(A7,GRILLA!A:M,12,0) -> 0.48024896 | C7: =RANK(B7,$B$2:$B$97) -> 6
A8: 431 | B8: =VLOOKUP(A8,GRILLA!A:M,12,0) -> 0.45025276 | C8: =RANK(B8,$B$2:$B$97) -> 7
A9: 316 | B9: =VLOOKUP(A9,GRILLA!A:M,12,0) -> 0.40070634 | C9: =RANK(B9,$B$2:$B$97) -> 8
A10: 210 | B10: =VLOOKUP(A10,GRILLA!A:M,12,0) -> 0.35627483 | C10: =RANK(B10,$B$2:$B$97) -> 9
A11: 423 | B11: =VLOOKUP(A11,GRILLA!A:M,12,0) -> 0.3554729 | C11: =RANK(B11,$B$2:$B$97) -> 10
A12: 317 | B12: =VLOOKUP(A12,GRILLA!A:M,12,0) -> 0.35263795 | C12: =RANK(B12,$B$2:$B$97) -> 11
A13: 430 | B13: =VLOOKUP(A13,GRILLA!A:M,12,0) -> 0.35200397 | C13: =RANK(B13,$B$2:$B$97) -> 12
... A97: 801 | B97: =VLOOKUP(A97,GRILLA!A:M,12,0) -> 0.04596437 | C97: =RANK(B97,$B$2:$B$97) -> 96

Sheet CLIENTES
E1: =VLOOKUP(B1,dinamica!B:L,3,0) -> #N/A | F1: =VLOOKUP(B1,dinamica!B:L,4,0) -> #N/A | G1: =VLOOKUP(B1,dinamica!B:L,5,0) -> #N/A | H1: =VLOOKUP(B1,dinamica!B:L,6,0) -> #N/A | I1: =VLOOKUP(B1,dinamica!B:L,7,0) -> #N/A | J1: =VLOOKUP(B1,dinamica!B:L,8,0) -> #N/A | K1: =VLOOKUP(B1,dinamica!B:L,9,0) -> #N/A | L1: =VLOOKUP(B1,dinamica!B:L,10,0) -> #N/A | M1: =VLOOKUP(B1,dinamica!B:L,11,0) -> #N/A
E2: 18 UNID | F2: 24 UNID | G2: 18 UNID | H2: 12 UNID | I2: 6 UNID | J2: 24 UNID | K2: 24 UNID | L2: 48 UNID | M2: 12 UNID
A3: RUTA | B3: SAP CLIENTE | C3: RAZON | D3: COD AS | E3: Hileret | F3: Elvive | G3: Carefree Siempre libre | H3: Calipso | I3: Nosotras | J3: Elegante | K3: Cif | L3: Arlistan Cruz Malta | M3: Downy | N3: Hileret | O3: Elvive | P3: Carefree Siempre libre | Q3: Calipso Nosotas | R3: Elegante | S3: Cif | T3: Arlistan Cruz Malta | U3: Downy
A4: 10 | B4: 1066802 | C4: TARUL S.A. | D4: =VLOOKUP(B4,'Maestro clientes'!A:C,3,0) -> 57295 | E4: 0 | F4: 0 | G4: 0 | H4: 0 | I4: 0 | J4: 0 | K4: 10 | L4: 0 | M4: 0 | N4: =IF(E4>=18,1,0) -> 0 | O4: =IF(F4>=24,1,0) -> 0 | P4: =IF(G4>=18,1,0) -> 0 | Q4: =IF(AND(H4>=12,I4>=6),1,0) -> 0 | R4: =IF(J4>=24,1,0) -> 0 | S4: =IF(K4>=24,1,0) -> 0 | T4: =IF(L4>=48,1,0) -> 0 | U4: =IF(M4>=12,1,0) -> 0
A5: 101 | B5: 1061366 | C5: NI ZHENGQIN | D5: =VLOOKUP(B5,'Maestro clientes'!A:C,3,0) -> 12255 | E5: 0 | F5: 0 | G5: 0 | H5: 0 | I5: 0 | J5: 0 | K5: 0 | L5: 20 | M5: 0 | N5: =IF(E5>=18,1,0) -> 0 | O5: =IF(F5>=24,1,0) -> 0 | P5: =IF(G5>=18,1,0) -> 0 | Q5: =IF(AND(H5>=12,I5>=6),1,0) -> 0 | R5: =IF(J5>=24,1,0) -> 0 | S5: =IF(K5>=24,1,0) -> 0 | T5: =IF(L5>=48,1,0) -> 0 | U5: =IF(M5>=12,1,0) -> 0
A6: 101 | B6: 1061605 | C6: HUANG QIAOXIONG | D6: =VLOOKUP(B6,'Maestro clientes'!A:C,3,0) -> 12565 | E6: 0 | F6: 0 | G6: 24 | H6: 0 | I6: 0 | J6: 0 | K6: 12 | L6: 0 | M6: 0 | N6: =IF(E6>=18,1,0) -> 0 | O6: =IF(F6>=24,1,0) -> 0 | P6: =IF(G6>=18,1,0) -> 1 | Q6: =IF(AND(H6>=12,I6>=6),1,0) -> 0 | R6: =IF(J6>=24,1,0) -> 0 | S6: =IF(K6>=24,1,0) -> 0 | T6: =IF(L6>=48,1,0) -> 0 | U6: =IF(M6>=12,1,0) -> 0
A7: 101 | B7: 1062285 | C7: ZHOU XIAOHONG | D7: =VLOOKUP(B7,'Maestro clientes'!A:C,3,0) -> 13546 | E7: 0 | F7: 0 | G7: 0 | H7: 0 | I7: 0 | J7: 0 | K7: 0 | L7: 12 | M7: 12 | N7: =IF(E7>=18,1,0) -> 0 | O7: =IF(F7>=24,1,0) -> 0 | P7: =IF(G7>=18,1,0) -> 0 | Q7: =IF(AND(H7>=12,I7>=6),1,0) -> 0 | R7: =IF(J7>=24,1,0) -> 0 | S7: =IF(K7>=24,1,0) -> 0 | T7: =IF(L7>=48,1,0) -> 0 | U7: =IF(M7>=12,1,0) -> 1
A8: 101 | B8: 1062433 | C8: CHEN KAILIN | D8: =VLOOKUP(B8,'Maestro clientes'!A:C,3,0) -> 13737 | E8: 0 | F8: 0 | G8: 0 | H8: 0 | I8: 0 | J8: 10 | K8: 0 | L8: 0 | M8: 0 | N8: =IF(E8>=18,1,0) -> 0 | O8: =IF(F8>=24,1,0) -> 0 | P8: =IF(G8>=18,1,0) -> 0 | Q8: =IF(AND(H8>=12,I8>=6),1,0) -> 0 | R8: =IF(J8>=24,1,0) -> 0 | S8: =IF(K8>=24,1,0) -> 0 | T8: =IF(L8>=48,1,0) -> 0 | U8: =IF(M8>=12,1,0) -> 0
A9: 101 | B9: 1065528 | C9: WU TAISEN | D9: =VLOOKUP(B9,'Maestro clientes'!A:C,3,0) -> 3700 | E9: 0 | F9: 32 | G9: 0 | H9: 0 | I9: 0 | J9: 0 | K9: 24 | L9: 0 | M9: 0 | N9: =IF(E9>=18,1,0) -> 0 | O9: =IF(F9>=24,1,0) -> 1 | P9: =IF(G9>=18,1,0) -> 0 | Q9: =IF(AND(H9>=12,I9>=6),1,0) -> 0 | R9: =IF(J9>=24,1,0) -> 0 | S9: =IF(K9>=24,1,0) -> 1 | T9: =IF(L9>=48,1,0) -> 0 | U9: =IF(M9>=12,1,0) -> 0
A10: 101 | B10: 1100122 | C10: LIN WENYONG | D10: =VLOOKUP(B10,'Maestro clientes'!A:C,3,0) -> 23570 | E10: 0 | F10: 0 | G10: 0 | H10: 0 | I10: 0 | J10: 0 | K10: 24 | L10: 0 | M10: 0 | N10: =IF(E10>=18,1,0) -> 0 | O10: =IF(F10>=24,1,0) -> 0 | P10: =IF(G10>=18,1,0) -> 0 | Q10: =IF(AND(H10>=12,I10>=6),1,0) -> 0 | R10: =IF(J10>=24,1,0) -> 0 | S10: =IF(K10>=24,1,0) -> 1 | T10: =IF(L10>=48,1,0) -> 0 | U10: =IF(M10>=12,1,0) -> 0
A11: 101 | B11: 1105377 | C11: YAN CAIYUN | D11: =VLOOKUP(B11,'Maestro clientes'!A:C,3,0) -> 24846 | E11: 0 | F11: 0 | G11: 0 | H11: 0 | I11: 0 | J11: 0 | K11: 12 | L11: 0 | M11: 0 | N11: =IF(E11>=18,1,0) -> 0 | O11: =IF(F11>=24,1,0) -> 0 | P11: =IF(G11>=18,1,0) -> 0 | Q11: =IF(AND(H11>=12,I11>=6),1,0) -> 0 | R11: =IF(J11>=24,1,0) -> 0 | S11: =IF(K11>=24,1,0) -> 0 | T11: =IF(L11>=48,1,0) -> 0 | U11: =IF(M11>=12,1,0) -> 0
A12: 101 | B12: 1106108 | C12: LIN MIN | D12: =VLOOKUP(B12,'Maestro clientes'!A:C,3,0) -> 25635 | E12: 0 | F12: 0 | G12: 0 | H12: 0 | I12: 0 | J12: 0 | K12: 0 | L12: 12 | M12: 0 | N12: =IF(E12>=18,1,0) -> 0 | O12: =IF(F12>=24,1,0) -> 0 | P12: =IF(G12>=18,1,0) -> 0 | Q12: =IF(AND(H12>=12,I12>=6),1,0) -> 0 | R12: =IF(J12>=24,1,0) -> 0 | S12: =IF(K12>=24,1,0) -> 0 | T12: =IF(L12>=48,1,0) -> 0 | U12: =IF(M12>=12,1,0) -> 0
A13: 101 | B13: 1108202 | C13: CHEN XING | D13: =VLOOKUP(B13,'Maestro clientes'!A:C,3,0) -> 28154 | E13: 0 | F13: 0 | G13: 0 | H13: 0 | I13: 0 | J13: 0 | K13: 0 | L13: 20 | M13: 0 | N13: =IF(E13>=18,1,0) -> 0 | O13: =IF(F13>=24,1,0) -> 0 | P13: =IF(G13>=18,1,0) -> 0 | Q13: =IF(AND(H13>=12,I13>=6),1,0) -> 0 | R13: =IF(J13>=24,1,0) -> 0 | S13: =IF(K13>=24,1,0) -> 0 | T13: =IF(L13>=48,1,0) -> 0 | U13: =IF(M13>=12,1,0) -> 0
A14: 101 | B14: 1110542 | C14: XIE XIAOMING | D14: =VLOOKUP(B14,'Maestro clientes'!A:C,3,0) -> 28673 | E14: 0 | F14: 0 | G14: 0 | H14: 0 | I14: 0 | J14: 0 | K14: 132 | L14: 24 | M14: 0 | N14: =IF(E14>=18,1,0) -> 0 | O14: =IF(F14>=24,1,0) -> 0 | P14: =IF(G14>=18,1,0) -> 0 | Q14: =IF(AND(H14>=12,I14>=6),1,0) -> 0 | R14: =IF(J14>=24,1,0) -> 0 | S14: =IF(K14>=24,1,0) -> 1 | T14: =IF(L14>=48,1,0) -> 0 | U14: =IF(M14>=12,1,0) -> 0
A15: 101 | B15: 1111877 | C15: CHEN GONGBO | D15: =VLOOKUP(B15,'Maestro clientes'!A:C,3,0) -> 29277 | E15: 0 | F15: 0 | G15: 18 | H15: 0 | I15: 0 | J15: 0 | K15: 0 | L15: 0 | M15: 0 | N15: =IF(E15>=18,1,0) -> 0 | O15: =IF(F15>=24,1,0) -> 0 | P15: =IF(G15>=18,1,0) -> 1 | Q15: =IF(AND(H15>=12,I15>=6),1,0) -> 0 | R15: =IF(J15>=24,1,0) -> 0 | S15: =IF(K15>=24,1,0) -> 0 | T15: =IF(L15>=48,1,0) -> 0 | U15: =IF(M15>=12,1,0) -> 0
... A2332: 950 | B2332: 1142458 | C2332: CASTRO GRACIELA EDITH | D2332: =VLOOKUP(B2332,'Maestro clientes'!A:C,3,0) -> 40788 | E2332: 0 | F2332: 0 | G2332: 0 | H2332: 0 | I2332: 0 | J2332: 10 | K2332: 1 | L2332: 0 | M2332: 0 | N2332: =IF(E2332>=18,1,0) -> 0 | O2332: =IF(F2332>=24,1,0) -> 0 | P2332: =IF(G2332>=18,1,0) -> 0 | Q2332: =IF(AND(H2332>=12,I2332>=6),1,0) -> 0 | R2332: =IF(J2332>=24,1,0) -> 0 | S2332: =IF(K2332>=24,1,0) -> 0 | T2332: =IF(L2332>=48,1,0) -> 0 | U2332: =IF(M2332>=12,1,0) -> 0

Sheet INCENTIVO
A1: N° de Ruta | B1: Nombre y apellido | C1: Hileret | F1: Elvive | I1: Carefree Siempre libre | L1: Calipso Nosotras | O1: Elegante | R1: Cif | U1: Arlistan Cruz Malta | X1: Categoria Pescados | AA1: Downy
C2: Obj CCC | D2: Ped CCC | E2: AV % | F2: Obj CCC | G2: Ped CCC | H2: AV % | I2: Obj CCC | J2: Ped CCC | K2: AV % | L2: Obj CCC | M2: Ped CCC | N2: AV % | O2: Obj CCC | P2: Ped CCC | Q2: AV % | R2: Obj ccc | S2: Ped CCC | T2: AV % | U2: Obj CCC | V2: Ped CCC | W2: AV % | X2: Obj $$ | Y2: Ped $$ | Z2: AV % | AA2: Obj CCC | AB2: Ped CCC | AC2: AV %
A3: 455 | B3: CISNEROS JONATHAN | C3: 13 | D3: =SUMIF(CLIENTES!A:A,INCENTIVO!A3,CLIENTES!N:N) -> 1 | E3: =IFERROR(D3/C3,0) -> 0.076923077 | F3: 13 | G3: =SUMIF(CLIENTES!A:A,INCENTIVO!A3,CLIENTES!O:O) -> 7 | H3: =IFERROR(G3/F3,0) -> 0.53846154 | I3: 14 | J3: =SUMIF(CLIENTES!A:A,INCENTIVO!A3,CLIENTES!P:P) -> 0 | K3: =IFERROR(J3/I3,0) -> 0 | L3: 14 | M3: =SUMIF(CLIENTES!A:A,INCENTIVO!A3,CLIENTES!Q:Q) -> 1 | N3: =IFERROR(M3/L3,0) -> 0.071428571 | O3: 11 | P3: =SUMIF(CLIENTES!A:A,INCENTIVO!A3,CLIENTES!R:R) -> 0 | Q3: =IFERROR(P3/O3,0) -> 0 | R3: 20 | S3: =SUMIF(CLIENTES!A:A,INCENTIVO!A3,CLIENTES!S:S) -> 3 | T3: =IFERROR(S3/R3,0) -> 0.15 | U3: 15 | V3: =SUMIF(CLIENTES!A:A,INCENTIVO!A3,CLIENTES!T:T) -> 1 | W3: =IFERROR(V3/U3,0) -> 0.066666667 | X3: 5000000 | Y3: =SUMIF('Bajada $$'!C:C,INCENTIVO!A3,'Bajada $$'!L:L) -> 187353.54 | Z3: =IFERROR(Y3/X3,0) -> 0.037470708 | AA3: 11 | AB3: =SUMIF(CLIENTES!A:A,INCENTIVO!A3,CLIENTES!U:U) -> 5 | AC3: =IFERROR(AB3/AA3,0) -> 0.45454545
A4: 480 | B4: MEDINA NICOLAS* | C4: 15 | D4: =SUMIF(CLIENTES!A:A,INCENTIVO!A4,CLIENTES!N:N) -> 3 | E4: =IFERROR(D4/C4,0) -> 0.2 | F4: 16 | G4: =SUMIF(CLIENTES!A:A,INCENTIVO!A4,CLIENTES!O:O) -> 8 | H4: =IFERROR(G4/F4,0) -> 0.5 | I4: 17 | J4: =SUMIF(CLIENTES!A:A,INCENTIVO!A4,CLIENTES!P:P) -> 5 | K4: =IFERROR(J4/I4,0) -> 0.29411765 | L4: 17 | M4: =SUMIF(CLIENTES!A:A,INCENTIVO!A4,CLIENTES!Q:Q) -> 3 | N4: =IFERROR(M4/L4,0) -> 0.17647059 | O4: 13 | P4: =SUMIF(CLIENTES!A:A,INCENTIVO!A4,CLIENTES!R:R) -> 2 | Q4: =IFERROR(P4/O4,0) -> 0.15384615 | R4: 23 | S4: =SUMIF(CLIENTES!A:A,INCENTIVO!A4,CLIENTES!S:S) -> 5 | T4: =IFERROR(S4/R4,0) -> 0.2173913 | U4: 18 | V4: =SUMIF(CLIENTES!A:A,INCENTIVO!A4,CLIENTES!T:T) -> 0 | W4: =IFERROR(V4/U4,0) -> 0 | X4: 3700000 | Y4: =SUMIF('Bajada $$'!C:C,INCENTIVO!A4,'Bajada $$'!L:L) -> 1202413.9 | Z4: =IFERROR(Y4/X4,0) -> 0.32497674 | AA4: 13 | AB4: =SUMIF(CLIENTES!A:A,INCENTIVO!A4,CLIENTES!U:U) -> 2 | AC4: =IFERROR(AB4/AA4,0) -> 0.15384615
A5: 430 | B5: DELAMANO BRIAN* | C5: 12 | D5: =SUMIF(CLIENTES!A:A,INCENTIVO!A5,CLIENTES!N:N) -> 2 | E5: =IFERROR(D5/C5,0) -> 0.16666667 | F5: 13 | G5: =SUMIF(CLIENTES!A:A,INCENTIVO!A5,CLIENTES!O:O) -> 19 | H5: =IFERROR(G5/F5,0) -> 1.4615385 | I5: 13 | J5: =SUMIF(CLIENTES!A:A,INCENTIVO!A5,CLIENTES!P:P) -> 7 | K5: =IFERROR(J5/I5,0) -> 0.53846154 | L5: 13 | M5: =SUMIF(CLIENTES!A:A,INCENTIVO!A5,CLIENTES!Q:Q) -> 0 | N5: =IFERROR(M5/L5,0) -> 0 | O5: 10 | P5: =SUMIF(CLIENTES!A:A,INCENTIVO!A5,CLIENTES!R:R) -> 1 | Q5: =IFERROR(P5/O5,0) -> 0.1 | R5: 19 | S5: =SUMIF(CLIENTES!A:A,INCENTIVO!A5,CLIENTES!S:S) -> 5 | T5: =IFERROR(S5/R5,0) -> 0.26315789 | U5: 14 | V5: =SUMIF(CLIENTES!A:A,INCENTIVO!A5,CLIENTES!T:T) -> 3 | W5: =IFERROR(V5/U5,0) -> 0.21428571 | X5: 4600000 | Y5: =SUMIF('Bajada $$'!C:C,INCENTIVO!A5,'Bajada $$'!L:L) -> 330838.86 | Z5: =IFERROR(Y5/X5,0) -> 0.071921491 | AA5: 10 | AB5: =SUMIF(CLIENTES!A:A,INCENTIVO!A5,CLIENTES!U:U) -> 6 | AC5: =IFERROR(AB5/AA5,0) -> 0.6
A6: 415 | B6: OLGUIN PATRICIA* | C6: 15 | D6: =SUMIF(CLIENTES!A:A,INCENTIVO!A6,CLIENTES!N:N) -> 8 | E6: =IFERROR(D6/C6,0) -> 0.53333333 | F6: 16 | G6: =SUMIF(CLIENTES!A:A,INCENTIVO!A6,CLIENTES!O:O) -> 4 | H6: =IFERROR(G6/F6,0) -> 0.25 | I6: 17 | J6: =SUMIF(CLIENTES!A:A,INCENTIVO!A6,CLIENTES!P:P) -> 5 | K6: =IFERROR(J6/I6,0) -> 0.29411765 | L6: 17 | M6: =SUMIF(CLIENTES!A:A,INCENTIVO!A6,CLIENTES!Q:Q) -> 1 | N6: =IFERROR(M6/L6,0) -> 0.058823529 | O6: 13 | P6: =SUMIF(CLIENTES!A:A,INCENTIVO!A6,CLIENTES!R:R) -> 0 | Q6: =IFERROR(P6/O6,0) -> 0 | R6: 25 | S6: =SUMIF(CLIENTES!A:A,INCENTIVO!A6,CLIENTES!S:S) -> 3 | T6: =IFERROR(S6/R6,0) -> 0.12 | U6: 18 | V6: =SUMIF(CLIENTES!A:A,INCENTIVO!A6,CLIENTES!T:T) -> 5 | W6: =IFERROR(V6/U6,0) -> 0.27777778 | X6: 4000000 | Y6: =SUMIF('Bajada $$'!C:C,INCENTIVO!A6,'Bajada $$'!L:L) -> 524338.44 | Z6: =IFERROR(Y6/X6,0) -> 0.13108461 | AA6: 13 | AB6: =SUMIF(CLIENTES!A:A,INCENTIVO!A6,CLIENTES!U:U) -> 2 | AC6: =IFERROR(AB6/AA6,0) -> 0.15384615
A7: 431 | B7: FERNANDEZ MELANY | C7: 13 | D7: =SUMIF(CLIENTES!A:A,INCENTIVO!A7,CLIENTES!N:N) -> 10 | E7: =IFERROR(D7/C7,0) -> 0.76923077 | F7: 14 | G7: =SUMIF(CLIENTES!A:A,INCENTIVO!A7,CLIENTES!O:O) -> 9 | H7: =IFERROR(G7/F7,0) -> 0.64285714 | I7: 15 | J7: =SUMIF(CLIENTES!A:A,INCENTIVO!A7,CLIENTES!P:P) -> 9 | K7: =IFERROR(J7/I7,0) -> 0.6 | L7: 15 | M7: =SUMIF(CLIENTES!A:A,INCENTIVO!A7,CLIENTES!Q:Q) -> 4 | N7: =IFERROR(M7/L7,0) -> 0.26666667 | O7: 12 | P7: =SUMIF(CLIENTES!A:A,INCENTIVO!A7,CLIENTES!R:R) -> 4 | Q7: =IFERROR(P7/O7,0) -> 0.33333333 | R7: 21 | S7: =SUMIF(CLIENTES!A:A,INCENTIVO!A7,CLIENTES!S:S) -> 6 | T7: =IFERROR(S7/R7,0) -> 0.28571429 | U7: 16 | V7: =SUMIF(CLIENTES!A:A,INCENTIVO!A7,CLIENTES!T:T) -> 5 | W7: =IFERROR(V7/U7,0) -> 0.3125 | X7: 5600000 | Y7: =SUMIF('Bajada $$'!C:C,INCENTIVO!A7,'Bajada $$'!L:L) -> 2193631.4 | Z7: =IFERROR(Y7/X7,0) -> 0.39171989 | AA7: 12 | AB7: =SUMIF(CLIENTES!A:A,INCENTIVO!A7,CLIENTES!U:U) -> 3 | AC7: =IFERROR(AB7/AA7,0) -> 0.25
